Watching for file changes with StatReloader
Not Found: /
Not Found: /
Not Found: /favicon.ico
Not Found: /
Not Found: /
Not Found: /
Internal Server Error: /logout/
Traceback (most recent call last):
  File "/home/ubuntu/venv/lib/python3.8/site-packages/django/core/handlers/exception.py", line 55, in inner
    response = get_response(request)
  File "/home/ubuntu/venv/lib/python3.8/site-packages/django/core/handlers/base.py", line 220, in _get_response
    response = response.render()
  File "/home/ubuntu/venv/lib/python3.8/site-packages/django/template/response.py", line 114, in render
    self.content = self.rendered_content
  File "/home/ubuntu/venv/lib/python3.8/site-packages/django/template/response.py", line 90, in rendered_content
    template = self.resolve_template(self.template_name)
  File "/home/ubuntu/venv/lib/python3.8/site-packages/django/template/response.py", line 72, in resolve_template
    return select_template(template, using=self.using)
  File "/home/ubuntu/venv/lib/python3.8/site-packages/django/template/loader.py", line 47, in select_template
    raise TemplateDoesNotExist(", ".join(template_name_list), chain=chain)
django.template.exceptions.TemplateDoesNotExist: registration/logged_out.html
Internal Server Error: /logout/
Traceback (most recent call last):
  File "/home/ubuntu/venv/lib/python3.8/site-packages/django/core/handlers/exception.py", line 55, in inner
    response = get_response(request)
  File "/home/ubuntu/venv/lib/python3.8/site-packages/django/core/handlers/base.py", line 220, in _get_response
    response = response.render()
  File "/home/ubuntu/venv/lib/python3.8/site-packages/django/template/response.py", line 114, in render
    self.content = self.rendered_content
  File "/home/ubuntu/venv/lib/python3.8/site-packages/django/template/response.py", line 90, in rendered_content
    template = self.resolve_template(self.template_name)
  File "/home/ubuntu/venv/lib/python3.8/site-packages/django/template/response.py", line 72, in resolve_template
    return select_template(template, using=self.using)
  File "/home/ubuntu/venv/lib/python3.8/site-packages/django/template/loader.py", line 47, in select_template
    raise TemplateDoesNotExist(", ".join(template_name_list), chain=chain)
django.template.exceptions.TemplateDoesNotExist: registration/logged_out.html
Not Found: /api
Not Found: /
Internal Server Error: /api/auth/register/
Traceback (most recent call last):
  File "/home/ubuntu/venv/lib/python3.8/site-packages/kombu/utils/functional.py", line 30, in __call__
    return self.__value__
AttributeError: 'ChannelPromise' object has no attribute '__value__'

During handling of the above exception, another exception occurred:

Traceback (most recent call last):
  File "/home/ubuntu/venv/lib/python3.8/site-packages/kombu/connection.py", line 446, in _reraise_as_library_errors
    yield
  File "/home/ubuntu/venv/lib/python3.8/site-packages/kombu/connection.py", line 433, in _ensure_connection
    return retry_over_time(
  File "/home/ubuntu/venv/lib/python3.8/site-packages/kombu/utils/functional.py", line 312, in retry_over_time
    return fun(*args, **kwargs)
  File "/home/ubuntu/venv/lib/python3.8/site-packages/kombu/connection.py", line 877, in _connection_factory
    self._connection = self._establish_connection()
  File "/home/ubuntu/venv/lib/python3.8/site-packages/kombu/connection.py", line 812, in _establish_connection
    conn = self.transport.establish_connection()
  File "/home/ubuntu/venv/lib/python3.8/site-packages/kombu/transport/pyamqp.py", line 201, in establish_connection
    conn.connect()
  File "/home/ubuntu/venv/lib/python3.8/site-packages/amqp/connection.py", line 323, in connect
    self.transport.connect()
  File "/home/ubuntu/venv/lib/python3.8/site-packages/amqp/transport.py", line 129, in connect
    self._connect(self.host, self.port, self.connect_timeout)
  File "/home/ubuntu/venv/lib/python3.8/site-packages/amqp/transport.py", line 184, in _connect
    self.sock.connect(sa)
ConnectionRefusedError: [Errno 111] Connection refused

The above exception was the direct cause of the following exception:

Traceback (most recent call last):
  File "/home/ubuntu/venv/lib/python3.8/site-packages/django/core/handlers/exception.py", line 55, in inner
    response = get_response(request)
  File "/home/ubuntu/venv/lib/python3.8/site-packages/django/core/handlers/base.py", line 197, in _get_response
    response = wrapped_callback(request, *callback_args, **callback_kwargs)
  File "/home/ubuntu/venv/lib/python3.8/site-packages/django/views/decorators/csrf.py", line 54, in wrapped_view
    return view_func(*args, **kwargs)
  File "/home/ubuntu/venv/lib/python3.8/site-packages/django/views/generic/base.py", line 103, in view
    return self.dispatch(request, *args, **kwargs)
  File "/home/ubuntu/venv/lib/python3.8/site-packages/rest_framework/views.py", line 509, in dispatch
    response = self.handle_exception(exc)
  File "/home/ubuntu/venv/lib/python3.8/site-packages/rest_framework/views.py", line 469, in handle_exception
    self.raise_uncaught_exception(exc)
  File "/home/ubuntu/venv/lib/python3.8/site-packages/rest_framework/views.py", line 480, in raise_uncaught_exception
    raise exc
  File "/home/ubuntu/venv/lib/python3.8/site-packages/rest_framework/views.py", line 506, in dispatch
    response = handler(request, *args, **kwargs)
  File "/home/ubuntu/workspace/common/views.py", line 324, in post
    send_email_to_new_user.delay(
  File "/home/ubuntu/venv/lib/python3.8/site-packages/celery/app/task.py", line 425, in delay
    return self.apply_async(args, kwargs)
  File "/home/ubuntu/venv/lib/python3.8/site-packages/celery/app/task.py", line 575, in apply_async
    return app.send_task(
  File "/home/ubuntu/venv/lib/python3.8/site-packages/celery/app/base.py", line 788, in send_task
    amqp.send_task_message(P, name, message, **options)
  File "/home/ubuntu/venv/lib/python3.8/site-packages/celery/app/amqp.py", line 510, in send_task_message
    ret = producer.publish(
  File "/home/ubuntu/venv/lib/python3.8/site-packages/kombu/messaging.py", line 177, in publish
    return _publish(
  File "/home/ubuntu/venv/lib/python3.8/site-packages/kombu/connection.py", line 523, in _ensured
    return fun(*args, **kwargs)
  File "/home/ubuntu/venv/lib/python3.8/site-packages/kombu/messaging.py", line 186, in _publish
    channel = self.channel
  File "/home/ubuntu/venv/lib/python3.8/site-packages/kombu/messaging.py", line 209, in _get_channel
    channel = self._channel = channel()
  File "/home/ubuntu/venv/lib/python3.8/site-packages/kombu/utils/functional.py", line 32, in __call__
    value = self.__value__ = self.__contract__()
  File "/home/ubuntu/venv/lib/python3.8/site-packages/kombu/messaging.py", line 225, in <lambda>
    channel = ChannelPromise(lambda: connection.default_channel)
  File "/home/ubuntu/venv/lib/python3.8/site-packages/kombu/connection.py", line 895, in default_channel
    self._ensure_connection(**conn_opts)
  File "/home/ubuntu/venv/lib/python3.8/site-packages/kombu/connection.py", line 433, in _ensure_connection
    return retry_over_time(
  File "/usr/lib/python3.8/contextlib.py", line 131, in __exit__
    self.gen.throw(type, value, traceback)
  File "/home/ubuntu/venv/lib/python3.8/site-packages/kombu/connection.py", line 450, in _reraise_as_library_errors
    raise ConnectionError(str(exc)) from exc
kombu.exceptions.OperationalError: [Errno 111] Connection refused
Watching for file changes with StatReloader
Not Found: /
Not Found: /favicon.ico
Not Found: /
Internal Server Error: /api/leads/
Traceback (most recent call last):
  File "/home/ubuntu/venv/lib/python3.8/site-packages/django/db/models/fields/__init__.py", line 2018, in get_prep_value
    return int(value)
ValueError: invalid literal for int() with base 10: 'null'

The above exception was the direct cause of the following exception:

Traceback (most recent call last):
  File "/home/ubuntu/venv/lib/python3.8/site-packages/django/core/handlers/exception.py", line 55, in inner
    response = get_response(request)
  File "/home/ubuntu/workspace/common/middleware/get_company.py", line 35, in __call__
    self.process_request(request)
  File "/home/ubuntu/workspace/common/middleware/get_company.py", line 47, in process_request
    org = Org.objects.get(id=org_id)
  File "/home/ubuntu/venv/lib/python3.8/site-packages/django/db/models/manager.py", line 85, in manager_method
    return getattr(self.get_queryset(), name)(*args, **kwargs)
  File "/home/ubuntu/venv/lib/python3.8/site-packages/django/db/models/query.py", line 636, in get
    clone = self._chain() if self.query.combinator else self.filter(*args, **kwargs)
  File "/home/ubuntu/venv/lib/python3.8/site-packages/django/db/models/query.py", line 1420, in filter
    return self._filter_or_exclude(False, args, kwargs)
  File "/home/ubuntu/venv/lib/python3.8/site-packages/django/db/models/query.py", line 1438, in _filter_or_exclude
    clone._filter_or_exclude_inplace(negate, args, kwargs)
  File "/home/ubuntu/venv/lib/python3.8/site-packages/django/db/models/query.py", line 1445, in _filter_or_exclude_inplace
    self._query.add_q(Q(*args, **kwargs))
  File "/home/ubuntu/venv/lib/python3.8/site-packages/django/db/models/sql/query.py", line 1532, in add_q
    clause, _ = self._add_q(q_object, self.used_aliases)
  File "/home/ubuntu/venv/lib/python3.8/site-packages/django/db/models/sql/query.py", line 1562, in _add_q
    child_clause, needed_inner = self.build_filter(
  File "/home/ubuntu/venv/lib/python3.8/site-packages/django/db/models/sql/query.py", line 1478, in build_filter
    condition = self.build_lookup(lookups, col, value)
  File "/home/ubuntu/venv/lib/python3.8/site-packages/django/db/models/sql/query.py", line 1303, in build_lookup
    lookup = lookup_class(lhs, rhs)
  File "/home/ubuntu/venv/lib/python3.8/site-packages/django/db/models/lookups.py", line 27, in __init__
    self.rhs = self.get_prep_lookup()
  File "/home/ubuntu/venv/lib/python3.8/site-packages/django/db/models/lookups.py", line 341, in get_prep_lookup
    return super().get_prep_lookup()
  File "/home/ubuntu/venv/lib/python3.8/site-packages/django/db/models/lookups.py", line 85, in get_prep_lookup
    return self.lhs.output_field.get_prep_value(self.rhs)
  File "/home/ubuntu/venv/lib/python3.8/site-packages/django/db/models/fields/__init__.py", line 2020, in get_prep_value
    raise e.__class__(
ValueError: Field 'id' expected a number but got 'null'.
Internal Server Error: /api/contacts/
Traceback (most recent call last):
  File "/home/ubuntu/venv/lib/python3.8/site-packages/django/db/models/fields/__init__.py", line 2018, in get_prep_value
    return int(value)
ValueError: invalid literal for int() with base 10: 'null'

The above exception was the direct cause of the following exception:

Traceback (most recent call last):
  File "/home/ubuntu/venv/lib/python3.8/site-packages/django/core/handlers/exception.py", line 55, in inner
    response = get_response(request)
  File "/home/ubuntu/workspace/common/middleware/get_company.py", line 35, in __call__
    self.process_request(request)
  File "/home/ubuntu/workspace/common/middleware/get_company.py", line 47, in process_request
    org = Org.objects.get(id=org_id)
  File "/home/ubuntu/venv/lib/python3.8/site-packages/django/db/models/manager.py", line 85, in manager_method
    return getattr(self.get_queryset(), name)(*args, **kwargs)
  File "/home/ubuntu/venv/lib/python3.8/site-packages/django/db/models/query.py", line 636, in get
    clone = self._chain() if self.query.combinator else self.filter(*args, **kwargs)
  File "/home/ubuntu/venv/lib/python3.8/site-packages/django/db/models/query.py", line 1420, in filter
    return self._filter_or_exclude(False, args, kwargs)
  File "/home/ubuntu/venv/lib/python3.8/site-packages/django/db/models/query.py", line 1438, in _filter_or_exclude
    clone._filter_or_exclude_inplace(negate, args, kwargs)
  File "/home/ubuntu/venv/lib/python3.8/site-packages/django/db/models/query.py", line 1445, in _filter_or_exclude_inplace
    self._query.add_q(Q(*args, **kwargs))
  File "/home/ubuntu/venv/lib/python3.8/site-packages/django/db/models/sql/query.py", line 1532, in add_q
    clause, _ = self._add_q(q_object, self.used_aliases)
  File "/home/ubuntu/venv/lib/python3.8/site-packages/django/db/models/sql/query.py", line 1562, in _add_q
    child_clause, needed_inner = self.build_filter(
  File "/home/ubuntu/venv/lib/python3.8/site-packages/django/db/models/sql/query.py", line 1478, in build_filter
    condition = self.build_lookup(lookups, col, value)
  File "/home/ubuntu/venv/lib/python3.8/site-packages/django/db/models/sql/query.py", line 1303, in build_lookup
    lookup = lookup_class(lhs, rhs)
  File "/home/ubuntu/venv/lib/python3.8/site-packages/django/db/models/lookups.py", line 27, in __init__
    self.rhs = self.get_prep_lookup()
  File "/home/ubuntu/venv/lib/python3.8/site-packages/django/db/models/lookups.py", line 341, in get_prep_lookup
    return super().get_prep_lookup()
  File "/home/ubuntu/venv/lib/python3.8/site-packages/django/db/models/lookups.py", line 85, in get_prep_lookup
    return self.lhs.output_field.get_prep_value(self.rhs)
  File "/home/ubuntu/venv/lib/python3.8/site-packages/django/db/models/fields/__init__.py", line 2020, in get_prep_value
    raise e.__class__(
ValueError: Field 'id' expected a number but got 'null'.
Internal Server Error: /api/opportunities/
Traceback (most recent call last):
  File "/home/ubuntu/venv/lib/python3.8/site-packages/django/db/models/fields/__init__.py", line 2018, in get_prep_value
    return int(value)
ValueError: invalid literal for int() with base 10: 'null'

The above exception was the direct cause of the following exception:

Traceback (most recent call last):
  File "/home/ubuntu/venv/lib/python3.8/site-packages/django/core/handlers/exception.py", line 55, in inner
    response = get_response(request)
  File "/home/ubuntu/workspace/common/middleware/get_company.py", line 35, in __call__
    self.process_request(request)
  File "/home/ubuntu/workspace/common/middleware/get_company.py", line 47, in process_request
    org = Org.objects.get(id=org_id)
  File "/home/ubuntu/venv/lib/python3.8/site-packages/django/db/models/manager.py", line 85, in manager_method
    return getattr(self.get_queryset(), name)(*args, **kwargs)
  File "/home/ubuntu/venv/lib/python3.8/site-packages/django/db/models/query.py", line 636, in get
    clone = self._chain() if self.query.combinator else self.filter(*args, **kwargs)
  File "/home/ubuntu/venv/lib/python3.8/site-packages/django/db/models/query.py", line 1420, in filter
    return self._filter_or_exclude(False, args, kwargs)
  File "/home/ubuntu/venv/lib/python3.8/site-packages/django/db/models/query.py", line 1438, in _filter_or_exclude
    clone._filter_or_exclude_inplace(negate, args, kwargs)
  File "/home/ubuntu/venv/lib/python3.8/site-packages/django/db/models/query.py", line 1445, in _filter_or_exclude_inplace
    self._query.add_q(Q(*args, **kwargs))
  File "/home/ubuntu/venv/lib/python3.8/site-packages/django/db/models/sql/query.py", line 1532, in add_q
    clause, _ = self._add_q(q_object, self.used_aliases)
  File "/home/ubuntu/venv/lib/python3.8/site-packages/django/db/models/sql/query.py", line 1562, in _add_q
    child_clause, needed_inner = self.build_filter(
  File "/home/ubuntu/venv/lib/python3.8/site-packages/django/db/models/sql/query.py", line 1478, in build_filter
    condition = self.build_lookup(lookups, col, value)
  File "/home/ubuntu/venv/lib/python3.8/site-packages/django/db/models/sql/query.py", line 1303, in build_lookup
    lookup = lookup_class(lhs, rhs)
  File "/home/ubuntu/venv/lib/python3.8/site-packages/django/db/models/lookups.py", line 27, in __init__
    self.rhs = self.get_prep_lookup()
  File "/home/ubuntu/venv/lib/python3.8/site-packages/django/db/models/lookups.py", line 341, in get_prep_lookup
    return super().get_prep_lookup()
  File "/home/ubuntu/venv/lib/python3.8/site-packages/django/db/models/lookups.py", line 85, in get_prep_lookup
    return self.lhs.output_field.get_prep_value(self.rhs)
  File "/home/ubuntu/venv/lib/python3.8/site-packages/django/db/models/fields/__init__.py", line 2020, in get_prep_value
    raise e.__class__(
ValueError: Field 'id' expected a number but got 'null'.
Internal Server Error: /api/accounts/
Traceback (most recent call last):
  File "/home/ubuntu/venv/lib/python3.8/site-packages/django/db/models/fields/__init__.py", line 2018, in get_prep_value
    return int(value)
ValueError: invalid literal for int() with base 10: 'null'

The above exception was the direct cause of the following exception:

Traceback (most recent call last):
  File "/home/ubuntu/venv/lib/python3.8/site-packages/django/core/handlers/exception.py", line 55, in inner
    response = get_response(request)
  File "/home/ubuntu/workspace/common/middleware/get_company.py", line 35, in __call__
    self.process_request(request)
  File "/home/ubuntu/workspace/common/middleware/get_company.py", line 47, in process_request
    org = Org.objects.get(id=org_id)
  File "/home/ubuntu/venv/lib/python3.8/site-packages/django/db/models/manager.py", line 85, in manager_method
    return getattr(self.get_queryset(), name)(*args, **kwargs)
  File "/home/ubuntu/venv/lib/python3.8/site-packages/django/db/models/query.py", line 636, in get
    clone = self._chain() if self.query.combinator else self.filter(*args, **kwargs)
  File "/home/ubuntu/venv/lib/python3.8/site-packages/django/db/models/query.py", line 1420, in filter
    return self._filter_or_exclude(False, args, kwargs)
  File "/home/ubuntu/venv/lib/python3.8/site-packages/django/db/models/query.py", line 1438, in _filter_or_exclude
    clone._filter_or_exclude_inplace(negate, args, kwargs)
  File "/home/ubuntu/venv/lib/python3.8/site-packages/django/db/models/query.py", line 1445, in _filter_or_exclude_inplace
    self._query.add_q(Q(*args, **kwargs))
  File "/home/ubuntu/venv/lib/python3.8/site-packages/django/db/models/sql/query.py", line 1532, in add_q
    clause, _ = self._add_q(q_object, self.used_aliases)
  File "/home/ubuntu/venv/lib/python3.8/site-packages/django/db/models/sql/query.py", line 1562, in _add_q
    child_clause, needed_inner = self.build_filter(
  File "/home/ubuntu/venv/lib/python3.8/site-packages/django/db/models/sql/query.py", line 1478, in build_filter
    condition = self.build_lookup(lookups, col, value)
  File "/home/ubuntu/venv/lib/python3.8/site-packages/django/db/models/sql/query.py", line 1303, in build_lookup
    lookup = lookup_class(lhs, rhs)
  File "/home/ubuntu/venv/lib/python3.8/site-packages/django/db/models/lookups.py", line 27, in __init__
    self.rhs = self.get_prep_lookup()
  File "/home/ubuntu/venv/lib/python3.8/site-packages/django/db/models/lookups.py", line 341, in get_prep_lookup
    return super().get_prep_lookup()
  File "/home/ubuntu/venv/lib/python3.8/site-packages/django/db/models/lookups.py", line 85, in get_prep_lookup
    return self.lhs.output_field.get_prep_value(self.rhs)
  File "/home/ubuntu/venv/lib/python3.8/site-packages/django/db/models/fields/__init__.py", line 2020, in get_prep_value
    raise e.__class__(
ValueError: Field 'id' expected a number but got 'null'.
Internal Server Error: /api/auth/companies-list/
Traceback (most recent call last):
  File "/home/ubuntu/venv/lib/python3.8/site-packages/django/db/models/fields/__init__.py", line 2018, in get_prep_value
    return int(value)
ValueError: invalid literal for int() with base 10: 'null'

The above exception was the direct cause of the following exception:

Traceback (most recent call last):
  File "/home/ubuntu/venv/lib/python3.8/site-packages/django/core/handlers/exception.py", line 55, in inner
    response = get_response(request)
  File "/home/ubuntu/workspace/common/middleware/get_company.py", line 35, in __call__
    self.process_request(request)
  File "/home/ubuntu/workspace/common/middleware/get_company.py", line 47, in process_request
    org = Org.objects.get(id=org_id)
  File "/home/ubuntu/venv/lib/python3.8/site-packages/django/db/models/manager.py", line 85, in manager_method
    return getattr(self.get_queryset(), name)(*args, **kwargs)
  File "/home/ubuntu/venv/lib/python3.8/site-packages/django/db/models/query.py", line 636, in get
    clone = self._chain() if self.query.combinator else self.filter(*args, **kwargs)
  File "/home/ubuntu/venv/lib/python3.8/site-packages/django/db/models/query.py", line 1420, in filter
    return self._filter_or_exclude(False, args, kwargs)
  File "/home/ubuntu/venv/lib/python3.8/site-packages/django/db/models/query.py", line 1438, in _filter_or_exclude
    clone._filter_or_exclude_inplace(negate, args, kwargs)
  File "/home/ubuntu/venv/lib/python3.8/site-packages/django/db/models/query.py", line 1445, in _filter_or_exclude_inplace
    self._query.add_q(Q(*args, **kwargs))
  File "/home/ubuntu/venv/lib/python3.8/site-packages/django/db/models/sql/query.py", line 1532, in add_q
    clause, _ = self._add_q(q_object, self.used_aliases)
  File "/home/ubuntu/venv/lib/python3.8/site-packages/django/db/models/sql/query.py", line 1562, in _add_q
    child_clause, needed_inner = self.build_filter(
  File "/home/ubuntu/venv/lib/python3.8/site-packages/django/db/models/sql/query.py", line 1478, in build_filter
    condition = self.build_lookup(lookups, col, value)
  File "/home/ubuntu/venv/lib/python3.8/site-packages/django/db/models/sql/query.py", line 1303, in build_lookup
    lookup = lookup_class(lhs, rhs)
  File "/home/ubuntu/venv/lib/python3.8/site-packages/django/db/models/lookups.py", line 27, in __init__
    self.rhs = self.get_prep_lookup()
  File "/home/ubuntu/venv/lib/python3.8/site-packages/django/db/models/lookups.py", line 341, in get_prep_lookup
    return super().get_prep_lookup()
  File "/home/ubuntu/venv/lib/python3.8/site-packages/django/db/models/lookups.py", line 85, in get_prep_lookup
    return self.lhs.output_field.get_prep_value(self.rhs)
  File "/home/ubuntu/venv/lib/python3.8/site-packages/django/db/models/fields/__init__.py", line 2020, in get_prep_value
    raise e.__class__(
ValueError: Field 'id' expected a number but got 'null'.
Internal Server Error: /api/users/
Traceback (most recent call last):
  File "/home/ubuntu/venv/lib/python3.8/site-packages/django/db/models/fields/__init__.py", line 2018, in get_prep_value
    return int(value)
ValueError: invalid literal for int() with base 10: 'null'

The above exception was the direct cause of the following exception:

Traceback (most recent call last):
  File "/home/ubuntu/venv/lib/python3.8/site-packages/django/core/handlers/exception.py", line 55, in inner
    response = get_response(request)
  File "/home/ubuntu/workspace/common/middleware/get_company.py", line 35, in __call__
    self.process_request(request)
  File "/home/ubuntu/workspace/common/middleware/get_company.py", line 47, in process_request
    org = Org.objects.get(id=org_id)
  File "/home/ubuntu/venv/lib/python3.8/site-packages/django/db/models/manager.py", line 85, in manager_method
    return getattr(self.get_queryset(), name)(*args, **kwargs)
  File "/home/ubuntu/venv/lib/python3.8/site-packages/django/db/models/query.py", line 636, in get
    clone = self._chain() if self.query.combinator else self.filter(*args, **kwargs)
  File "/home/ubuntu/venv/lib/python3.8/site-packages/django/db/models/query.py", line 1420, in filter
    return self._filter_or_exclude(False, args, kwargs)
  File "/home/ubuntu/venv/lib/python3.8/site-packages/django/db/models/query.py", line 1438, in _filter_or_exclude
    clone._filter_or_exclude_inplace(negate, args, kwargs)
  File "/home/ubuntu/venv/lib/python3.8/site-packages/django/db/models/query.py", line 1445, in _filter_or_exclude_inplace
    self._query.add_q(Q(*args, **kwargs))
  File "/home/ubuntu/venv/lib/python3.8/site-packages/django/db/models/sql/query.py", line 1532, in add_q
    clause, _ = self._add_q(q_object, self.used_aliases)
  File "/home/ubuntu/venv/lib/python3.8/site-packages/django/db/models/sql/query.py", line 1562, in _add_q
    child_clause, needed_inner = self.build_filter(
  File "/home/ubuntu/venv/lib/python3.8/site-packages/django/db/models/sql/query.py", line 1478, in build_filter
    condition = self.build_lookup(lookups, col, value)
  File "/home/ubuntu/venv/lib/python3.8/site-packages/django/db/models/sql/query.py", line 1303, in build_lookup
    lookup = lookup_class(lhs, rhs)
  File "/home/ubuntu/venv/lib/python3.8/site-packages/django/db/models/lookups.py", line 27, in __init__
    self.rhs = self.get_prep_lookup()
  File "/home/ubuntu/venv/lib/python3.8/site-packages/django/db/models/lookups.py", line 341, in get_prep_lookup
    return super().get_prep_lookup()
  File "/home/ubuntu/venv/lib/python3.8/site-packages/django/db/models/lookups.py", line 85, in get_prep_lookup
    return self.lhs.output_field.get_prep_value(self.rhs)
  File "/home/ubuntu/venv/lib/python3.8/site-packages/django/db/models/fields/__init__.py", line 2020, in get_prep_value
    raise e.__class__(
ValueError: Field 'id' expected a number but got 'null'.
Internal Server Error: /api/cases/
Traceback (most recent call last):
  File "/home/ubuntu/venv/lib/python3.8/site-packages/django/db/models/fields/__init__.py", line 2018, in get_prep_value
    return int(value)
ValueError: invalid literal for int() with base 10: 'null'

The above exception was the direct cause of the following exception:

Traceback (most recent call last):
  File "/home/ubuntu/venv/lib/python3.8/site-packages/django/core/handlers/exception.py", line 55, in inner
    response = get_response(request)
  File "/home/ubuntu/workspace/common/middleware/get_company.py", line 35, in __call__
    self.process_request(request)
  File "/home/ubuntu/workspace/common/middleware/get_company.py", line 47, in process_request
    org = Org.objects.get(id=org_id)
  File "/home/ubuntu/venv/lib/python3.8/site-packages/django/db/models/manager.py", line 85, in manager_method
    return getattr(self.get_queryset(), name)(*args, **kwargs)
  File "/home/ubuntu/venv/lib/python3.8/site-packages/django/db/models/query.py", line 636, in get
    clone = self._chain() if self.query.combinator else self.filter(*args, **kwargs)
  File "/home/ubuntu/venv/lib/python3.8/site-packages/django/db/models/query.py", line 1420, in filter
    return self._filter_or_exclude(False, args, kwargs)
  File "/home/ubuntu/venv/lib/python3.8/site-packages/django/db/models/query.py", line 1438, in _filter_or_exclude
    clone._filter_or_exclude_inplace(negate, args, kwargs)
  File "/home/ubuntu/venv/lib/python3.8/site-packages/django/db/models/query.py", line 1445, in _filter_or_exclude_inplace
    self._query.add_q(Q(*args, **kwargs))
  File "/home/ubuntu/venv/lib/python3.8/site-packages/django/db/models/sql/query.py", line 1532, in add_q
    clause, _ = self._add_q(q_object, self.used_aliases)
  File "/home/ubuntu/venv/lib/python3.8/site-packages/django/db/models/sql/query.py", line 1562, in _add_q
    child_clause, needed_inner = self.build_filter(
  File "/home/ubuntu/venv/lib/python3.8/site-packages/django/db/models/sql/query.py", line 1478, in build_filter
    condition = self.build_lookup(lookups, col, value)
  File "/home/ubuntu/venv/lib/python3.8/site-packages/django/db/models/sql/query.py", line 1303, in build_lookup
    lookup = lookup_class(lhs, rhs)
  File "/home/ubuntu/venv/lib/python3.8/site-packages/django/db/models/lookups.py", line 27, in __init__
    self.rhs = self.get_prep_lookup()
  File "/home/ubuntu/venv/lib/python3.8/site-packages/django/db/models/lookups.py", line 341, in get_prep_lookup
    return super().get_prep_lookup()
  File "/home/ubuntu/venv/lib/python3.8/site-packages/django/db/models/lookups.py", line 85, in get_prep_lookup
    return self.lhs.output_field.get_prep_value(self.rhs)
  File "/home/ubuntu/venv/lib/python3.8/site-packages/django/db/models/fields/__init__.py", line 2020, in get_prep_value
    raise e.__class__(
ValueError: Field 'id' expected a number but got 'null'.
Internal Server Error: /api/contacts/
Traceback (most recent call last):
  File "/home/ubuntu/venv/lib/python3.8/site-packages/django/db/models/fields/__init__.py", line 2018, in get_prep_value
    return int(value)
ValueError: invalid literal for int() with base 10: 'null'

The above exception was the direct cause of the following exception:

Traceback (most recent call last):
  File "/home/ubuntu/venv/lib/python3.8/site-packages/django/core/handlers/exception.py", line 55, in inner
    response = get_response(request)
  File "/home/ubuntu/workspace/common/middleware/get_company.py", line 35, in __call__
    self.process_request(request)
  File "/home/ubuntu/workspace/common/middleware/get_company.py", line 47, in process_request
    org = Org.objects.get(id=org_id)
  File "/home/ubuntu/venv/lib/python3.8/site-packages/django/db/models/manager.py", line 85, in manager_method
    return getattr(self.get_queryset(), name)(*args, **kwargs)
  File "/home/ubuntu/venv/lib/python3.8/site-packages/django/db/models/query.py", line 636, in get
    clone = self._chain() if self.query.combinator else self.filter(*args, **kwargs)
  File "/home/ubuntu/venv/lib/python3.8/site-packages/django/db/models/query.py", line 1420, in filter
    return self._filter_or_exclude(False, args, kwargs)
  File "/home/ubuntu/venv/lib/python3.8/site-packages/django/db/models/query.py", line 1438, in _filter_or_exclude
    clone._filter_or_exclude_inplace(negate, args, kwargs)
  File "/home/ubuntu/venv/lib/python3.8/site-packages/django/db/models/query.py", line 1445, in _filter_or_exclude_inplace
    self._query.add_q(Q(*args, **kwargs))
  File "/home/ubuntu/venv/lib/python3.8/site-packages/django/db/models/sql/query.py", line 1532, in add_q
    clause, _ = self._add_q(q_object, self.used_aliases)
  File "/home/ubuntu/venv/lib/python3.8/site-packages/django/db/models/sql/query.py", line 1562, in _add_q
    child_clause, needed_inner = self.build_filter(
  File "/home/ubuntu/venv/lib/python3.8/site-packages/django/db/models/sql/query.py", line 1478, in build_filter
    condition = self.build_lookup(lookups, col, value)
  File "/home/ubuntu/venv/lib/python3.8/site-packages/django/db/models/sql/query.py", line 1303, in build_lookup
    lookup = lookup_class(lhs, rhs)
  File "/home/ubuntu/venv/lib/python3.8/site-packages/django/db/models/lookups.py", line 27, in __init__
    self.rhs = self.get_prep_lookup()
  File "/home/ubuntu/venv/lib/python3.8/site-packages/django/db/models/lookups.py", line 341, in get_prep_lookup
    return super().get_prep_lookup()
  File "/home/ubuntu/venv/lib/python3.8/site-packages/django/db/models/lookups.py", line 85, in get_prep_lookup
    return self.lhs.output_field.get_prep_value(self.rhs)
  File "/home/ubuntu/venv/lib/python3.8/site-packages/django/db/models/fields/__init__.py", line 2020, in get_prep_value
    raise e.__class__(
ValueError: Field 'id' expected a number but got 'null'.
Internal Server Error: /api/leads/
Traceback (most recent call last):
  File "/home/ubuntu/venv/lib/python3.8/site-packages/django/db/models/fields/__init__.py", line 2018, in get_prep_value
    return int(value)
ValueError: invalid literal for int() with base 10: 'null'

The above exception was the direct cause of the following exception:

Traceback (most recent call last):
  File "/home/ubuntu/venv/lib/python3.8/site-packages/django/core/handlers/exception.py", line 55, in inner
    response = get_response(request)
  File "/home/ubuntu/workspace/common/middleware/get_company.py", line 35, in __call__
    self.process_request(request)
  File "/home/ubuntu/workspace/common/middleware/get_company.py", line 47, in process_request
    org = Org.objects.get(id=org_id)
  File "/home/ubuntu/venv/lib/python3.8/site-packages/django/db/models/manager.py", line 85, in manager_method
    return getattr(self.get_queryset(), name)(*args, **kwargs)
  File "/home/ubuntu/venv/lib/python3.8/site-packages/django/db/models/query.py", line 636, in get
    clone = self._chain() if self.query.combinator else self.filter(*args, **kwargs)
  File "/home/ubuntu/venv/lib/python3.8/site-packages/django/db/models/query.py", line 1420, in filter
    return self._filter_or_exclude(False, args, kwargs)
  File "/home/ubuntu/venv/lib/python3.8/site-packages/django/db/models/query.py", line 1438, in _filter_or_exclude
    clone._filter_or_exclude_inplace(negate, args, kwargs)
  File "/home/ubuntu/venv/lib/python3.8/site-packages/django/db/models/query.py", line 1445, in _filter_or_exclude_inplace
    self._query.add_q(Q(*args, **kwargs))
  File "/home/ubuntu/venv/lib/python3.8/site-packages/django/db/models/sql/query.py", line 1532, in add_q
    clause, _ = self._add_q(q_object, self.used_aliases)
  File "/home/ubuntu/venv/lib/python3.8/site-packages/django/db/models/sql/query.py", line 1562, in _add_q
    child_clause, needed_inner = self.build_filter(
  File "/home/ubuntu/venv/lib/python3.8/site-packages/django/db/models/sql/query.py", line 1478, in build_filter
    condition = self.build_lookup(lookups, col, value)
  File "/home/ubuntu/venv/lib/python3.8/site-packages/django/db/models/sql/query.py", line 1303, in build_lookup
    lookup = lookup_class(lhs, rhs)
  File "/home/ubuntu/venv/lib/python3.8/site-packages/django/db/models/lookups.py", line 27, in __init__
    self.rhs = self.get_prep_lookup()
  File "/home/ubuntu/venv/lib/python3.8/site-packages/django/db/models/lookups.py", line 341, in get_prep_lookup
    return super().get_prep_lookup()
  File "/home/ubuntu/venv/lib/python3.8/site-packages/django/db/models/lookups.py", line 85, in get_prep_lookup
    return self.lhs.output_field.get_prep_value(self.rhs)
  File "/home/ubuntu/venv/lib/python3.8/site-packages/django/db/models/fields/__init__.py", line 2020, in get_prep_value
    raise e.__class__(
ValueError: Field 'id' expected a number but got 'null'.
Internal Server Error: /api/opportunities/
Traceback (most recent call last):
  File "/home/ubuntu/venv/lib/python3.8/site-packages/django/db/models/fields/__init__.py", line 2018, in get_prep_value
    return int(value)
ValueError: invalid literal for int() with base 10: 'null'

The above exception was the direct cause of the following exception:

Traceback (most recent call last):
  File "/home/ubuntu/venv/lib/python3.8/site-packages/django/core/handlers/exception.py", line 55, in inner
    response = get_response(request)
  File "/home/ubuntu/workspace/common/middleware/get_company.py", line 35, in __call__
    self.process_request(request)
  File "/home/ubuntu/workspace/common/middleware/get_company.py", line 47, in process_request
    org = Org.objects.get(id=org_id)
  File "/home/ubuntu/venv/lib/python3.8/site-packages/django/db/models/manager.py", line 85, in manager_method
    return getattr(self.get_queryset(), name)(*args, **kwargs)
  File "/home/ubuntu/venv/lib/python3.8/site-packages/django/db/models/query.py", line 636, in get
    clone = self._chain() if self.query.combinator else self.filter(*args, **kwargs)
  File "/home/ubuntu/venv/lib/python3.8/site-packages/django/db/models/query.py", line 1420, in filter
    return self._filter_or_exclude(False, args, kwargs)
  File "/home/ubuntu/venv/lib/python3.8/site-packages/django/db/models/query.py", line 1438, in _filter_or_exclude
    clone._filter_or_exclude_inplace(negate, args, kwargs)
  File "/home/ubuntu/venv/lib/python3.8/site-packages/django/db/models/query.py", line 1445, in _filter_or_exclude_inplace
    self._query.add_q(Q(*args, **kwargs))
  File "/home/ubuntu/venv/lib/python3.8/site-packages/django/db/models/sql/query.py", line 1532, in add_q
    clause, _ = self._add_q(q_object, self.used_aliases)
  File "/home/ubuntu/venv/lib/python3.8/site-packages/django/db/models/sql/query.py", line 1562, in _add_q
    child_clause, needed_inner = self.build_filter(
  File "/home/ubuntu/venv/lib/python3.8/site-packages/django/db/models/sql/query.py", line 1478, in build_filter
    condition = self.build_lookup(lookups, col, value)
  File "/home/ubuntu/venv/lib/python3.8/site-packages/django/db/models/sql/query.py", line 1303, in build_lookup
    lookup = lookup_class(lhs, rhs)
  File "/home/ubuntu/venv/lib/python3.8/site-packages/django/db/models/lookups.py", line 27, in __init__
    self.rhs = self.get_prep_lookup()
  File "/home/ubuntu/venv/lib/python3.8/site-packages/django/db/models/lookups.py", line 341, in get_prep_lookup
    return super().get_prep_lookup()
  File "/home/ubuntu/venv/lib/python3.8/site-packages/django/db/models/lookups.py", line 85, in get_prep_lookup
    return self.lhs.output_field.get_prep_value(self.rhs)
  File "/home/ubuntu/venv/lib/python3.8/site-packages/django/db/models/fields/__init__.py", line 2020, in get_prep_value
    raise e.__class__(
ValueError: Field 'id' expected a number but got 'null'.
Internal Server Error: /api/leads/
Traceback (most recent call last):
  File "/home/ubuntu/venv/lib/python3.8/site-packages/django/db/models/fields/__init__.py", line 2018, in get_prep_value
    return int(value)
ValueError: invalid literal for int() with base 10: 'null'

The above exception was the direct cause of the following exception:

Traceback (most recent call last):
  File "/home/ubuntu/venv/lib/python3.8/site-packages/django/core/handlers/exception.py", line 55, in inner
    response = get_response(request)
  File "/home/ubuntu/workspace/common/middleware/get_company.py", line 35, in __call__
    self.process_request(request)
  File "/home/ubuntu/workspace/common/middleware/get_company.py", line 47, in process_request
    org = Org.objects.get(id=org_id)
  File "/home/ubuntu/venv/lib/python3.8/site-packages/django/db/models/manager.py", line 85, in manager_method
    return getattr(self.get_queryset(), name)(*args, **kwargs)
  File "/home/ubuntu/venv/lib/python3.8/site-packages/django/db/models/query.py", line 636, in get
    clone = self._chain() if self.query.combinator else self.filter(*args, **kwargs)
  File "/home/ubuntu/venv/lib/python3.8/site-packages/django/db/models/query.py", line 1420, in filter
    return self._filter_or_exclude(False, args, kwargs)
  File "/home/ubuntu/venv/lib/python3.8/site-packages/django/db/models/query.py", line 1438, in _filter_or_exclude
    clone._filter_or_exclude_inplace(negate, args, kwargs)
  File "/home/ubuntu/venv/lib/python3.8/site-packages/django/db/models/query.py", line 1445, in _filter_or_exclude_inplace
    self._query.add_q(Q(*args, **kwargs))
  File "/home/ubuntu/venv/lib/python3.8/site-packages/django/db/models/sql/query.py", line 1532, in add_q
    clause, _ = self._add_q(q_object, self.used_aliases)
  File "/home/ubuntu/venv/lib/python3.8/site-packages/django/db/models/sql/query.py", line 1562, in _add_q
    child_clause, needed_inner = self.build_filter(
  File "/home/ubuntu/venv/lib/python3.8/site-packages/django/db/models/sql/query.py", line 1478, in build_filter
    condition = self.build_lookup(lookups, col, value)
  File "/home/ubuntu/venv/lib/python3.8/site-packages/django/db/models/sql/query.py", line 1303, in build_lookup
    lookup = lookup_class(lhs, rhs)
  File "/home/ubuntu/venv/lib/python3.8/site-packages/django/db/models/lookups.py", line 27, in __init__
    self.rhs = self.get_prep_lookup()
  File "/home/ubuntu/venv/lib/python3.8/site-packages/django/db/models/lookups.py", line 341, in get_prep_lookup
    return super().get_prep_lookup()
  File "/home/ubuntu/venv/lib/python3.8/site-packages/django/db/models/lookups.py", line 85, in get_prep_lookup
    return self.lhs.output_field.get_prep_value(self.rhs)
  File "/home/ubuntu/venv/lib/python3.8/site-packages/django/db/models/fields/__init__.py", line 2020, in get_prep_value
    raise e.__class__(
ValueError: Field 'id' expected a number but got 'null'.
Unauthorized: /api/leads/
/home/ubuntu/workspace/leads/views.py changed, reloading.
Watching for file changes with StatReloader
/home/ubuntu/workspace/leads/views.py changed, reloading.
Watching for file changes with StatReloader
/home/ubuntu/workspace/leads/views.py changed, reloading.
Watching for file changes with StatReloader
/home/ubuntu/workspace/leads/views.py changed, reloading.
Watching for file changes with StatReloader
/home/ubuntu/workspace/leads/views.py changed, reloading.
Watching for file changes with StatReloader
/home/ubuntu/workspace/leads/views.py changed, reloading.
Watching for file changes with StatReloader
/home/ubuntu/workspace/leads/views.py changed, reloading.
Watching for file changes with StatReloader
Internal Server Error: /api/leads/
Traceback (most recent call last):
  File "/home/ubuntu/venv/lib/python3.8/site-packages/django/db/models/fields/__init__.py", line 2018, in get_prep_value
    return int(value)
ValueError: invalid literal for int() with base 10: 'null'

The above exception was the direct cause of the following exception:

Traceback (most recent call last):
  File "/home/ubuntu/venv/lib/python3.8/site-packages/django/core/handlers/exception.py", line 55, in inner
    response = get_response(request)
  File "/home/ubuntu/workspace/common/middleware/get_company.py", line 35, in __call__
    self.process_request(request)
  File "/home/ubuntu/workspace/common/middleware/get_company.py", line 47, in process_request
    org = Org.objects.get(id=org_id)
  File "/home/ubuntu/venv/lib/python3.8/site-packages/django/db/models/manager.py", line 85, in manager_method
    return getattr(self.get_queryset(), name)(*args, **kwargs)
  File "/home/ubuntu/venv/lib/python3.8/site-packages/django/db/models/query.py", line 636, in get
    clone = self._chain() if self.query.combinator else self.filter(*args, **kwargs)
  File "/home/ubuntu/venv/lib/python3.8/site-packages/django/db/models/query.py", line 1420, in filter
    return self._filter_or_exclude(False, args, kwargs)
  File "/home/ubuntu/venv/lib/python3.8/site-packages/django/db/models/query.py", line 1438, in _filter_or_exclude
    clone._filter_or_exclude_inplace(negate, args, kwargs)
  File "/home/ubuntu/venv/lib/python3.8/site-packages/django/db/models/query.py", line 1445, in _filter_or_exclude_inplace
    self._query.add_q(Q(*args, **kwargs))
  File "/home/ubuntu/venv/lib/python3.8/site-packages/django/db/models/sql/query.py", line 1532, in add_q
    clause, _ = self._add_q(q_object, self.used_aliases)
  File "/home/ubuntu/venv/lib/python3.8/site-packages/django/db/models/sql/query.py", line 1562, in _add_q
    child_clause, needed_inner = self.build_filter(
  File "/home/ubuntu/venv/lib/python3.8/site-packages/django/db/models/sql/query.py", line 1478, in build_filter
    condition = self.build_lookup(lookups, col, value)
  File "/home/ubuntu/venv/lib/python3.8/site-packages/django/db/models/sql/query.py", line 1303, in build_lookup
    lookup = lookup_class(lhs, rhs)
  File "/home/ubuntu/venv/lib/python3.8/site-packages/django/db/models/lookups.py", line 27, in __init__
    self.rhs = self.get_prep_lookup()
  File "/home/ubuntu/venv/lib/python3.8/site-packages/django/db/models/lookups.py", line 341, in get_prep_lookup
    return super().get_prep_lookup()
  File "/home/ubuntu/venv/lib/python3.8/site-packages/django/db/models/lookups.py", line 85, in get_prep_lookup
    return self.lhs.output_field.get_prep_value(self.rhs)
  File "/home/ubuntu/venv/lib/python3.8/site-packages/django/db/models/fields/__init__.py", line 2020, in get_prep_value
    raise e.__class__(
ValueError: Field 'id' expected a number but got 'null'.
Internal Server Error: /api/leads/
Traceback (most recent call last):
  File "/home/ubuntu/venv/lib/python3.8/site-packages/rest_framework/request.py", line 416, in __getattr__
    return getattr(self._request, attr)
AttributeError: 'WSGIRequest' object has no attribute 'org'

During handling of the above exception, another exception occurred:

Traceback (most recent call last):
  File "/home/ubuntu/venv/lib/python3.8/site-packages/django/core/handlers/exception.py", line 55, in inner
    response = get_response(request)
  File "/home/ubuntu/venv/lib/python3.8/site-packages/django/core/handlers/base.py", line 197, in _get_response
    response = wrapped_callback(request, *callback_args, **callback_kwargs)
  File "/home/ubuntu/venv/lib/python3.8/site-packages/django/views/decorators/csrf.py", line 54, in wrapped_view
    return view_func(*args, **kwargs)
  File "/home/ubuntu/venv/lib/python3.8/site-packages/django/views/generic/base.py", line 103, in view
    return self.dispatch(request, *args, **kwargs)
  File "/home/ubuntu/venv/lib/python3.8/site-packages/rest_framework/views.py", line 509, in dispatch
    response = self.handle_exception(exc)
  File "/home/ubuntu/venv/lib/python3.8/site-packages/rest_framework/views.py", line 469, in handle_exception
    self.raise_uncaught_exception(exc)
  File "/home/ubuntu/venv/lib/python3.8/site-packages/rest_framework/views.py", line 480, in raise_uncaught_exception
    raise exc
  File "/home/ubuntu/venv/lib/python3.8/site-packages/rest_framework/views.py", line 506, in dispatch
    response = handler(request, *args, **kwargs)
  File "/home/ubuntu/workspace/leads/views.py", line 150, in get
    context = self.get_context_data(**kwargs)
  File "/home/ubuntu/workspace/leads/views.py", line 52, in get_context_data
    self.model.objects.filter(org=self.request.org)
  File "/home/ubuntu/venv/lib/python3.8/site-packages/rest_framework/request.py", line 418, in __getattr__
    return self.__getattribute__(attr)
AttributeError: 'Request' object has no attribute 'org'
Internal Server Error: /api/contacts/
Traceback (most recent call last):
  File "/home/ubuntu/venv/lib/python3.8/site-packages/django/db/models/fields/__init__.py", line 2018, in get_prep_value
    return int(value)
ValueError: invalid literal for int() with base 10: 'null'

The above exception was the direct cause of the following exception:

Traceback (most recent call last):
  File "/home/ubuntu/venv/lib/python3.8/site-packages/django/core/handlers/exception.py", line 55, in inner
    response = get_response(request)
  File "/home/ubuntu/workspace/common/middleware/get_company.py", line 35, in __call__
    self.process_request(request)
  File "/home/ubuntu/workspace/common/middleware/get_company.py", line 47, in process_request
    org = Org.objects.get(id=org_id)
  File "/home/ubuntu/venv/lib/python3.8/site-packages/django/db/models/manager.py", line 85, in manager_method
    return getattr(self.get_queryset(), name)(*args, **kwargs)
  File "/home/ubuntu/venv/lib/python3.8/site-packages/django/db/models/query.py", line 636, in get
    clone = self._chain() if self.query.combinator else self.filter(*args, **kwargs)
  File "/home/ubuntu/venv/lib/python3.8/site-packages/django/db/models/query.py", line 1420, in filter
    return self._filter_or_exclude(False, args, kwargs)
  File "/home/ubuntu/venv/lib/python3.8/site-packages/django/db/models/query.py", line 1438, in _filter_or_exclude
    clone._filter_or_exclude_inplace(negate, args, kwargs)
  File "/home/ubuntu/venv/lib/python3.8/site-packages/django/db/models/query.py", line 1445, in _filter_or_exclude_inplace
    self._query.add_q(Q(*args, **kwargs))
  File "/home/ubuntu/venv/lib/python3.8/site-packages/django/db/models/sql/query.py", line 1532, in add_q
    clause, _ = self._add_q(q_object, self.used_aliases)
  File "/home/ubuntu/venv/lib/python3.8/site-packages/django/db/models/sql/query.py", line 1562, in _add_q
    child_clause, needed_inner = self.build_filter(
  File "/home/ubuntu/venv/lib/python3.8/site-packages/django/db/models/sql/query.py", line 1478, in build_filter
    condition = self.build_lookup(lookups, col, value)
  File "/home/ubuntu/venv/lib/python3.8/site-packages/django/db/models/sql/query.py", line 1303, in build_lookup
    lookup = lookup_class(lhs, rhs)
  File "/home/ubuntu/venv/lib/python3.8/site-packages/django/db/models/lookups.py", line 27, in __init__
    self.rhs = self.get_prep_lookup()
  File "/home/ubuntu/venv/lib/python3.8/site-packages/django/db/models/lookups.py", line 341, in get_prep_lookup
    return super().get_prep_lookup()
  File "/home/ubuntu/venv/lib/python3.8/site-packages/django/db/models/lookups.py", line 85, in get_prep_lookup
    return self.lhs.output_field.get_prep_value(self.rhs)
  File "/home/ubuntu/venv/lib/python3.8/site-packages/django/db/models/fields/__init__.py", line 2020, in get_prep_value
    raise e.__class__(
ValueError: Field 'id' expected a number but got 'null'.
Internal Server Error: /api/opportunities/
Traceback (most recent call last):
  File "/home/ubuntu/venv/lib/python3.8/site-packages/django/db/models/fields/__init__.py", line 2018, in get_prep_value
    return int(value)
ValueError: invalid literal for int() with base 10: 'null'

The above exception was the direct cause of the following exception:

Traceback (most recent call last):
  File "/home/ubuntu/venv/lib/python3.8/site-packages/django/core/handlers/exception.py", line 55, in inner
    response = get_response(request)
  File "/home/ubuntu/workspace/common/middleware/get_company.py", line 35, in __call__
    self.process_request(request)
  File "/home/ubuntu/workspace/common/middleware/get_company.py", line 47, in process_request
    org = Org.objects.get(id=org_id)
  File "/home/ubuntu/venv/lib/python3.8/site-packages/django/db/models/manager.py", line 85, in manager_method
    return getattr(self.get_queryset(), name)(*args, **kwargs)
  File "/home/ubuntu/venv/lib/python3.8/site-packages/django/db/models/query.py", line 636, in get
    clone = self._chain() if self.query.combinator else self.filter(*args, **kwargs)
  File "/home/ubuntu/venv/lib/python3.8/site-packages/django/db/models/query.py", line 1420, in filter
    return self._filter_or_exclude(False, args, kwargs)
  File "/home/ubuntu/venv/lib/python3.8/site-packages/django/db/models/query.py", line 1438, in _filter_or_exclude
    clone._filter_or_exclude_inplace(negate, args, kwargs)
  File "/home/ubuntu/venv/lib/python3.8/site-packages/django/db/models/query.py", line 1445, in _filter_or_exclude_inplace
    self._query.add_q(Q(*args, **kwargs))
  File "/home/ubuntu/venv/lib/python3.8/site-packages/django/db/models/sql/query.py", line 1532, in add_q
    clause, _ = self._add_q(q_object, self.used_aliases)
  File "/home/ubuntu/venv/lib/python3.8/site-packages/django/db/models/sql/query.py", line 1562, in _add_q
    child_clause, needed_inner = self.build_filter(
  File "/home/ubuntu/venv/lib/python3.8/site-packages/django/db/models/sql/query.py", line 1478, in build_filter
    condition = self.build_lookup(lookups, col, value)
  File "/home/ubuntu/venv/lib/python3.8/site-packages/django/db/models/sql/query.py", line 1303, in build_lookup
    lookup = lookup_class(lhs, rhs)
  File "/home/ubuntu/venv/lib/python3.8/site-packages/django/db/models/lookups.py", line 27, in __init__
    self.rhs = self.get_prep_lookup()
  File "/home/ubuntu/venv/lib/python3.8/site-packages/django/db/models/lookups.py", line 341, in get_prep_lookup
    return super().get_prep_lookup()
  File "/home/ubuntu/venv/lib/python3.8/site-packages/django/db/models/lookups.py", line 85, in get_prep_lookup
    return self.lhs.output_field.get_prep_value(self.rhs)
  File "/home/ubuntu/venv/lib/python3.8/site-packages/django/db/models/fields/__init__.py", line 2020, in get_prep_value
    raise e.__class__(
ValueError: Field 'id' expected a number but got 'null'.
Internal Server Error: /api/accounts/
Traceback (most recent call last):
  File "/home/ubuntu/venv/lib/python3.8/site-packages/django/db/models/fields/__init__.py", line 2018, in get_prep_value
    return int(value)
ValueError: invalid literal for int() with base 10: 'null'

The above exception was the direct cause of the following exception:

Traceback (most recent call last):
  File "/home/ubuntu/venv/lib/python3.8/site-packages/django/core/handlers/exception.py", line 55, in inner
    response = get_response(request)
  File "/home/ubuntu/workspace/common/middleware/get_company.py", line 35, in __call__
    self.process_request(request)
  File "/home/ubuntu/workspace/common/middleware/get_company.py", line 47, in process_request
    org = Org.objects.get(id=org_id)
  File "/home/ubuntu/venv/lib/python3.8/site-packages/django/db/models/manager.py", line 85, in manager_method
    return getattr(self.get_queryset(), name)(*args, **kwargs)
  File "/home/ubuntu/venv/lib/python3.8/site-packages/django/db/models/query.py", line 636, in get
    clone = self._chain() if self.query.combinator else self.filter(*args, **kwargs)
  File "/home/ubuntu/venv/lib/python3.8/site-packages/django/db/models/query.py", line 1420, in filter
    return self._filter_or_exclude(False, args, kwargs)
  File "/home/ubuntu/venv/lib/python3.8/site-packages/django/db/models/query.py", line 1438, in _filter_or_exclude
    clone._filter_or_exclude_inplace(negate, args, kwargs)
  File "/home/ubuntu/venv/lib/python3.8/site-packages/django/db/models/query.py", line 1445, in _filter_or_exclude_inplace
    self._query.add_q(Q(*args, **kwargs))
  File "/home/ubuntu/venv/lib/python3.8/site-packages/django/db/models/sql/query.py", line 1532, in add_q
    clause, _ = self._add_q(q_object, self.used_aliases)
  File "/home/ubuntu/venv/lib/python3.8/site-packages/django/db/models/sql/query.py", line 1562, in _add_q
    child_clause, needed_inner = self.build_filter(
  File "/home/ubuntu/venv/lib/python3.8/site-packages/django/db/models/sql/query.py", line 1478, in build_filter
    condition = self.build_lookup(lookups, col, value)
  File "/home/ubuntu/venv/lib/python3.8/site-packages/django/db/models/sql/query.py", line 1303, in build_lookup
    lookup = lookup_class(lhs, rhs)
  File "/home/ubuntu/venv/lib/python3.8/site-packages/django/db/models/lookups.py", line 27, in __init__
    self.rhs = self.get_prep_lookup()
  File "/home/ubuntu/venv/lib/python3.8/site-packages/django/db/models/lookups.py", line 341, in get_prep_lookup
    return super().get_prep_lookup()
  File "/home/ubuntu/venv/lib/python3.8/site-packages/django/db/models/lookups.py", line 85, in get_prep_lookup
    return self.lhs.output_field.get_prep_value(self.rhs)
  File "/home/ubuntu/venv/lib/python3.8/site-packages/django/db/models/fields/__init__.py", line 2020, in get_prep_value
    raise e.__class__(
ValueError: Field 'id' expected a number but got 'null'.
Internal Server Error: /api/auth/companies-list/
Traceback (most recent call last):
  File "/home/ubuntu/venv/lib/python3.8/site-packages/django/db/models/fields/__init__.py", line 2018, in get_prep_value
    return int(value)
ValueError: invalid literal for int() with base 10: 'null'

The above exception was the direct cause of the following exception:

Traceback (most recent call last):
  File "/home/ubuntu/venv/lib/python3.8/site-packages/django/core/handlers/exception.py", line 55, in inner
    response = get_response(request)
  File "/home/ubuntu/workspace/common/middleware/get_company.py", line 35, in __call__
    self.process_request(request)
  File "/home/ubuntu/workspace/common/middleware/get_company.py", line 47, in process_request
    org = Org.objects.get(id=org_id)
  File "/home/ubuntu/venv/lib/python3.8/site-packages/django/db/models/manager.py", line 85, in manager_method
    return getattr(self.get_queryset(), name)(*args, **kwargs)
  File "/home/ubuntu/venv/lib/python3.8/site-packages/django/db/models/query.py", line 636, in get
    clone = self._chain() if self.query.combinator else self.filter(*args, **kwargs)
  File "/home/ubuntu/venv/lib/python3.8/site-packages/django/db/models/query.py", line 1420, in filter
    return self._filter_or_exclude(False, args, kwargs)
  File "/home/ubuntu/venv/lib/python3.8/site-packages/django/db/models/query.py", line 1438, in _filter_or_exclude
    clone._filter_or_exclude_inplace(negate, args, kwargs)
  File "/home/ubuntu/venv/lib/python3.8/site-packages/django/db/models/query.py", line 1445, in _filter_or_exclude_inplace
    self._query.add_q(Q(*args, **kwargs))
  File "/home/ubuntu/venv/lib/python3.8/site-packages/django/db/models/sql/query.py", line 1532, in add_q
    clause, _ = self._add_q(q_object, self.used_aliases)
  File "/home/ubuntu/venv/lib/python3.8/site-packages/django/db/models/sql/query.py", line 1562, in _add_q
    child_clause, needed_inner = self.build_filter(
  File "/home/ubuntu/venv/lib/python3.8/site-packages/django/db/models/sql/query.py", line 1478, in build_filter
    condition = self.build_lookup(lookups, col, value)
  File "/home/ubuntu/venv/lib/python3.8/site-packages/django/db/models/sql/query.py", line 1303, in build_lookup
    lookup = lookup_class(lhs, rhs)
  File "/home/ubuntu/venv/lib/python3.8/site-packages/django/db/models/lookups.py", line 27, in __init__
    self.rhs = self.get_prep_lookup()
  File "/home/ubuntu/venv/lib/python3.8/site-packages/django/db/models/lookups.py", line 341, in get_prep_lookup
    return super().get_prep_lookup()
  File "/home/ubuntu/venv/lib/python3.8/site-packages/django/db/models/lookups.py", line 85, in get_prep_lookup
    return self.lhs.output_field.get_prep_value(self.rhs)
  File "/home/ubuntu/venv/lib/python3.8/site-packages/django/db/models/fields/__init__.py", line 2020, in get_prep_value
    raise e.__class__(
ValueError: Field 'id' expected a number but got 'null'.
Internal Server Error: /api/users/
Traceback (most recent call last):
  File "/home/ubuntu/venv/lib/python3.8/site-packages/django/db/models/fields/__init__.py", line 2018, in get_prep_value
    return int(value)
ValueError: invalid literal for int() with base 10: 'null'

The above exception was the direct cause of the following exception:

Traceback (most recent call last):
  File "/home/ubuntu/venv/lib/python3.8/site-packages/django/core/handlers/exception.py", line 55, in inner
    response = get_response(request)
  File "/home/ubuntu/workspace/common/middleware/get_company.py", line 35, in __call__
    self.process_request(request)
  File "/home/ubuntu/workspace/common/middleware/get_company.py", line 47, in process_request
    org = Org.objects.get(id=org_id)
  File "/home/ubuntu/venv/lib/python3.8/site-packages/django/db/models/manager.py", line 85, in manager_method
    return getattr(self.get_queryset(), name)(*args, **kwargs)
  File "/home/ubuntu/venv/lib/python3.8/site-packages/django/db/models/query.py", line 636, in get
    clone = self._chain() if self.query.combinator else self.filter(*args, **kwargs)
  File "/home/ubuntu/venv/lib/python3.8/site-packages/django/db/models/query.py", line 1420, in filter
    return self._filter_or_exclude(False, args, kwargs)
  File "/home/ubuntu/venv/lib/python3.8/site-packages/django/db/models/query.py", line 1438, in _filter_or_exclude
    clone._filter_or_exclude_inplace(negate, args, kwargs)
  File "/home/ubuntu/venv/lib/python3.8/site-packages/django/db/models/query.py", line 1445, in _filter_or_exclude_inplace
    self._query.add_q(Q(*args, **kwargs))
  File "/home/ubuntu/venv/lib/python3.8/site-packages/django/db/models/sql/query.py", line 1532, in add_q
    clause, _ = self._add_q(q_object, self.used_aliases)
  File "/home/ubuntu/venv/lib/python3.8/site-packages/django/db/models/sql/query.py", line 1562, in _add_q
    child_clause, needed_inner = self.build_filter(
  File "/home/ubuntu/venv/lib/python3.8/site-packages/django/db/models/sql/query.py", line 1478, in build_filter
    condition = self.build_lookup(lookups, col, value)
  File "/home/ubuntu/venv/lib/python3.8/site-packages/django/db/models/sql/query.py", line 1303, in build_lookup
    lookup = lookup_class(lhs, rhs)
  File "/home/ubuntu/venv/lib/python3.8/site-packages/django/db/models/lookups.py", line 27, in __init__
    self.rhs = self.get_prep_lookup()
  File "/home/ubuntu/venv/lib/python3.8/site-packages/django/db/models/lookups.py", line 341, in get_prep_lookup
    return super().get_prep_lookup()
  File "/home/ubuntu/venv/lib/python3.8/site-packages/django/db/models/lookups.py", line 85, in get_prep_lookup
    return self.lhs.output_field.get_prep_value(self.rhs)
  File "/home/ubuntu/venv/lib/python3.8/site-packages/django/db/models/fields/__init__.py", line 2020, in get_prep_value
    raise e.__class__(
ValueError: Field 'id' expected a number but got 'null'.
Internal Server Error: /api/cases/
Traceback (most recent call last):
  File "/home/ubuntu/venv/lib/python3.8/site-packages/django/db/models/fields/__init__.py", line 2018, in get_prep_value
    return int(value)
ValueError: invalid literal for int() with base 10: 'null'

The above exception was the direct cause of the following exception:

Traceback (most recent call last):
  File "/home/ubuntu/venv/lib/python3.8/site-packages/django/core/handlers/exception.py", line 55, in inner
    response = get_response(request)
  File "/home/ubuntu/workspace/common/middleware/get_company.py", line 35, in __call__
    self.process_request(request)
  File "/home/ubuntu/workspace/common/middleware/get_company.py", line 47, in process_request
    org = Org.objects.get(id=org_id)
  File "/home/ubuntu/venv/lib/python3.8/site-packages/django/db/models/manager.py", line 85, in manager_method
    return getattr(self.get_queryset(), name)(*args, **kwargs)
  File "/home/ubuntu/venv/lib/python3.8/site-packages/django/db/models/query.py", line 636, in get
    clone = self._chain() if self.query.combinator else self.filter(*args, **kwargs)
  File "/home/ubuntu/venv/lib/python3.8/site-packages/django/db/models/query.py", line 1420, in filter
    return self._filter_or_exclude(False, args, kwargs)
  File "/home/ubuntu/venv/lib/python3.8/site-packages/django/db/models/query.py", line 1438, in _filter_or_exclude
    clone._filter_or_exclude_inplace(negate, args, kwargs)
  File "/home/ubuntu/venv/lib/python3.8/site-packages/django/db/models/query.py", line 1445, in _filter_or_exclude_inplace
    self._query.add_q(Q(*args, **kwargs))
  File "/home/ubuntu/venv/lib/python3.8/site-packages/django/db/models/sql/query.py", line 1532, in add_q
    clause, _ = self._add_q(q_object, self.used_aliases)
  File "/home/ubuntu/venv/lib/python3.8/site-packages/django/db/models/sql/query.py", line 1562, in _add_q
    child_clause, needed_inner = self.build_filter(
  File "/home/ubuntu/venv/lib/python3.8/site-packages/django/db/models/sql/query.py", line 1478, in build_filter
    condition = self.build_lookup(lookups, col, value)
  File "/home/ubuntu/venv/lib/python3.8/site-packages/django/db/models/sql/query.py", line 1303, in build_lookup
    lookup = lookup_class(lhs, rhs)
  File "/home/ubuntu/venv/lib/python3.8/site-packages/django/db/models/lookups.py", line 27, in __init__
    self.rhs = self.get_prep_lookup()
  File "/home/ubuntu/venv/lib/python3.8/site-packages/django/db/models/lookups.py", line 341, in get_prep_lookup
    return super().get_prep_lookup()
  File "/home/ubuntu/venv/lib/python3.8/site-packages/django/db/models/lookups.py", line 85, in get_prep_lookup
    return self.lhs.output_field.get_prep_value(self.rhs)
  File "/home/ubuntu/venv/lib/python3.8/site-packages/django/db/models/fields/__init__.py", line 2020, in get_prep_value
    raise e.__class__(
ValueError: Field 'id' expected a number but got 'null'.
Watching for file changes with StatReloader
Not Found: /
Not Found: /favicon.ico
Internal Server Error: /api/leads/
Traceback (most recent call last):
  File "/home/ubuntu/venv/lib/python3.8/site-packages/django/db/models/fields/__init__.py", line 2018, in get_prep_value
    return int(value)
ValueError: invalid literal for int() with base 10: 'null'

The above exception was the direct cause of the following exception:

Traceback (most recent call last):
  File "/home/ubuntu/venv/lib/python3.8/site-packages/django/core/handlers/exception.py", line 55, in inner
    response = get_response(request)
  File "/home/ubuntu/workspace/common/middleware/get_company.py", line 35, in __call__
    self.process_request(request)
  File "/home/ubuntu/workspace/common/middleware/get_company.py", line 47, in process_request
    org = Org.objects.get(id=org_id)
  File "/home/ubuntu/venv/lib/python3.8/site-packages/django/db/models/manager.py", line 85, in manager_method
    return getattr(self.get_queryset(), name)(*args, **kwargs)
  File "/home/ubuntu/venv/lib/python3.8/site-packages/django/db/models/query.py", line 636, in get
    clone = self._chain() if self.query.combinator else self.filter(*args, **kwargs)
  File "/home/ubuntu/venv/lib/python3.8/site-packages/django/db/models/query.py", line 1420, in filter
    return self._filter_or_exclude(False, args, kwargs)
  File "/home/ubuntu/venv/lib/python3.8/site-packages/django/db/models/query.py", line 1438, in _filter_or_exclude
    clone._filter_or_exclude_inplace(negate, args, kwargs)
  File "/home/ubuntu/venv/lib/python3.8/site-packages/django/db/models/query.py", line 1445, in _filter_or_exclude_inplace
    self._query.add_q(Q(*args, **kwargs))
  File "/home/ubuntu/venv/lib/python3.8/site-packages/django/db/models/sql/query.py", line 1532, in add_q
    clause, _ = self._add_q(q_object, self.used_aliases)
  File "/home/ubuntu/venv/lib/python3.8/site-packages/django/db/models/sql/query.py", line 1562, in _add_q
    child_clause, needed_inner = self.build_filter(
  File "/home/ubuntu/venv/lib/python3.8/site-packages/django/db/models/sql/query.py", line 1478, in build_filter
    condition = self.build_lookup(lookups, col, value)
  File "/home/ubuntu/venv/lib/python3.8/site-packages/django/db/models/sql/query.py", line 1303, in build_lookup
    lookup = lookup_class(lhs, rhs)
  File "/home/ubuntu/venv/lib/python3.8/site-packages/django/db/models/lookups.py", line 27, in __init__
    self.rhs = self.get_prep_lookup()
  File "/home/ubuntu/venv/lib/python3.8/site-packages/django/db/models/lookups.py", line 341, in get_prep_lookup
    return super().get_prep_lookup()
  File "/home/ubuntu/venv/lib/python3.8/site-packages/django/db/models/lookups.py", line 85, in get_prep_lookup
    return self.lhs.output_field.get_prep_value(self.rhs)
  File "/home/ubuntu/venv/lib/python3.8/site-packages/django/db/models/fields/__init__.py", line 2020, in get_prep_value
    raise e.__class__(
ValueError: Field 'id' expected a number but got 'null'.
Internal Server Error: /api/leads/
Traceback (most recent call last):
  File "/home/ubuntu/venv/lib/python3.8/site-packages/django/db/models/fields/__init__.py", line 2018, in get_prep_value
    return int(value)
ValueError: invalid literal for int() with base 10: 'null'

The above exception was the direct cause of the following exception:

Traceback (most recent call last):
  File "/home/ubuntu/venv/lib/python3.8/site-packages/django/core/handlers/exception.py", line 55, in inner
    response = get_response(request)
  File "/home/ubuntu/workspace/common/middleware/get_company.py", line 35, in __call__
    self.process_request(request)
  File "/home/ubuntu/workspace/common/middleware/get_company.py", line 47, in process_request
    org = Org.objects.get(id=org_id)
  File "/home/ubuntu/venv/lib/python3.8/site-packages/django/db/models/manager.py", line 85, in manager_method
    return getattr(self.get_queryset(), name)(*args, **kwargs)
  File "/home/ubuntu/venv/lib/python3.8/site-packages/django/db/models/query.py", line 636, in get
    clone = self._chain() if self.query.combinator else self.filter(*args, **kwargs)
  File "/home/ubuntu/venv/lib/python3.8/site-packages/django/db/models/query.py", line 1420, in filter
    return self._filter_or_exclude(False, args, kwargs)
  File "/home/ubuntu/venv/lib/python3.8/site-packages/django/db/models/query.py", line 1438, in _filter_or_exclude
    clone._filter_or_exclude_inplace(negate, args, kwargs)
  File "/home/ubuntu/venv/lib/python3.8/site-packages/django/db/models/query.py", line 1445, in _filter_or_exclude_inplace
    self._query.add_q(Q(*args, **kwargs))
  File "/home/ubuntu/venv/lib/python3.8/site-packages/django/db/models/sql/query.py", line 1532, in add_q
    clause, _ = self._add_q(q_object, self.used_aliases)
  File "/home/ubuntu/venv/lib/python3.8/site-packages/django/db/models/sql/query.py", line 1562, in _add_q
    child_clause, needed_inner = self.build_filter(
  File "/home/ubuntu/venv/lib/python3.8/site-packages/django/db/models/sql/query.py", line 1478, in build_filter
    condition = self.build_lookup(lookups, col, value)
  File "/home/ubuntu/venv/lib/python3.8/site-packages/django/db/models/sql/query.py", line 1303, in build_lookup
    lookup = lookup_class(lhs, rhs)
  File "/home/ubuntu/venv/lib/python3.8/site-packages/django/db/models/lookups.py", line 27, in __init__
    self.rhs = self.get_prep_lookup()
  File "/home/ubuntu/venv/lib/python3.8/site-packages/django/db/models/lookups.py", line 341, in get_prep_lookup
    return super().get_prep_lookup()
  File "/home/ubuntu/venv/lib/python3.8/site-packages/django/db/models/lookups.py", line 85, in get_prep_lookup
    return self.lhs.output_field.get_prep_value(self.rhs)
  File "/home/ubuntu/venv/lib/python3.8/site-packages/django/db/models/fields/__init__.py", line 2020, in get_prep_value
    raise e.__class__(
ValueError: Field 'id' expected a number but got 'null'.
Not Found: /api
/home/ubuntu/workspace/crm/urls.py changed, reloading.
Watching for file changes with StatReloader
/home/ubuntu/workspace/crm/urls.py changed, reloading.
Watching for file changes with StatReloader
Not Found: /api
/home/ubuntu/workspace/crm/urls.py changed, reloading.
Watching for file changes with StatReloader
Not Found: /api
Not Found: /api/
/home/ubuntu/workspace/crm/urls.py changed, reloading.
Watching for file changes with StatReloader
Not Found: /api/
Unauthorized: /api/dashboard/
/home/ubuntu/workspace/common/views.py changed, reloading.
Watching for file changes with StatReloader
Internal Server Error: /api/dashboard/
Traceback (most recent call last):
  File "/home/ubuntu/venv/lib/python3.8/site-packages/rest_framework/request.py", line 416, in __getattr__
    return getattr(self._request, attr)
AttributeError: 'WSGIRequest' object has no attribute 'org'

During handling of the above exception, another exception occurred:

Traceback (most recent call last):
  File "/home/ubuntu/venv/lib/python3.8/site-packages/django/core/handlers/exception.py", line 55, in inner
    response = get_response(request)
  File "/home/ubuntu/venv/lib/python3.8/site-packages/django/core/handlers/base.py", line 197, in _get_response
    response = wrapped_callback(request, *callback_args, **callback_kwargs)
  File "/home/ubuntu/venv/lib/python3.8/site-packages/django/views/decorators/csrf.py", line 54, in wrapped_view
    return view_func(*args, **kwargs)
  File "/home/ubuntu/venv/lib/python3.8/site-packages/django/views/generic/base.py", line 103, in view
    return self.dispatch(request, *args, **kwargs)
  File "/home/ubuntu/venv/lib/python3.8/site-packages/rest_framework/views.py", line 509, in dispatch
    response = self.handle_exception(exc)
  File "/home/ubuntu/venv/lib/python3.8/site-packages/rest_framework/views.py", line 469, in handle_exception
    self.raise_uncaught_exception(exc)
  File "/home/ubuntu/venv/lib/python3.8/site-packages/rest_framework/views.py", line 480, in raise_uncaught_exception
    raise exc
  File "/home/ubuntu/venv/lib/python3.8/site-packages/rest_framework/views.py", line 506, in dispatch
    response = handler(request, *args, **kwargs)
  File "/home/ubuntu/workspace/common/views.py", line 250, in get
    accounts = Account.objects.filter(status="open", org=request.org)
  File "/home/ubuntu/venv/lib/python3.8/site-packages/rest_framework/request.py", line 418, in __getattr__
    return self.__getattribute__(attr)
AttributeError: 'Request' object has no attribute 'org'
/home/ubuntu/workspace/common/views.py changed, reloading.
Watching for file changes with StatReloader
/home/ubuntu/workspace/crm/urls.py changed, reloading.
Watching for file changes with StatReloader
Internal Server Error: /api/accounts/
Traceback (most recent call last):
  File "/home/ubuntu/venv/lib/python3.8/site-packages/django/db/models/fields/__init__.py", line 2018, in get_prep_value
    return int(value)
ValueError: invalid literal for int() with base 10: 'null'

The above exception was the direct cause of the following exception:

Traceback (most recent call last):
  File "/home/ubuntu/venv/lib/python3.8/site-packages/django/core/handlers/exception.py", line 55, in inner
    response = get_response(request)
  File "/home/ubuntu/workspace/common/middleware/get_company.py", line 35, in __call__
    self.process_request(request)
  File "/home/ubuntu/workspace/common/middleware/get_company.py", line 47, in process_request
    org = Org.objects.get(id=org_id)
  File "/home/ubuntu/venv/lib/python3.8/site-packages/django/db/models/manager.py", line 85, in manager_method
    return getattr(self.get_queryset(), name)(*args, **kwargs)
  File "/home/ubuntu/venv/lib/python3.8/site-packages/django/db/models/query.py", line 636, in get
    clone = self._chain() if self.query.combinator else self.filter(*args, **kwargs)
  File "/home/ubuntu/venv/lib/python3.8/site-packages/django/db/models/query.py", line 1420, in filter
    return self._filter_or_exclude(False, args, kwargs)
  File "/home/ubuntu/venv/lib/python3.8/site-packages/django/db/models/query.py", line 1438, in _filter_or_exclude
    clone._filter_or_exclude_inplace(negate, args, kwargs)
  File "/home/ubuntu/venv/lib/python3.8/site-packages/django/db/models/query.py", line 1445, in _filter_or_exclude_inplace
    self._query.add_q(Q(*args, **kwargs))
  File "/home/ubuntu/venv/lib/python3.8/site-packages/django/db/models/sql/query.py", line 1532, in add_q
    clause, _ = self._add_q(q_object, self.used_aliases)
  File "/home/ubuntu/venv/lib/python3.8/site-packages/django/db/models/sql/query.py", line 1562, in _add_q
    child_clause, needed_inner = self.build_filter(
  File "/home/ubuntu/venv/lib/python3.8/site-packages/django/db/models/sql/query.py", line 1478, in build_filter
    condition = self.build_lookup(lookups, col, value)
  File "/home/ubuntu/venv/lib/python3.8/site-packages/django/db/models/sql/query.py", line 1303, in build_lookup
    lookup = lookup_class(lhs, rhs)
  File "/home/ubuntu/venv/lib/python3.8/site-packages/django/db/models/lookups.py", line 27, in __init__
    self.rhs = self.get_prep_lookup()
  File "/home/ubuntu/venv/lib/python3.8/site-packages/django/db/models/lookups.py", line 341, in get_prep_lookup
    return super().get_prep_lookup()
  File "/home/ubuntu/venv/lib/python3.8/site-packages/django/db/models/lookups.py", line 85, in get_prep_lookup
    return self.lhs.output_field.get_prep_value(self.rhs)
  File "/home/ubuntu/venv/lib/python3.8/site-packages/django/db/models/fields/__init__.py", line 2020, in get_prep_value
    raise e.__class__(
ValueError: Field 'id' expected a number but got 'null'.
Internal Server Error: /api/auth/companies-list/
Traceback (most recent call last):
  File "/home/ubuntu/venv/lib/python3.8/site-packages/django/db/models/fields/__init__.py", line 2018, in get_prep_value
    return int(value)
ValueError: invalid literal for int() with base 10: 'null'

The above exception was the direct cause of the following exception:

Traceback (most recent call last):
  File "/home/ubuntu/venv/lib/python3.8/site-packages/django/core/handlers/exception.py", line 55, in inner
    response = get_response(request)
  File "/home/ubuntu/workspace/common/middleware/get_company.py", line 35, in __call__
    self.process_request(request)
  File "/home/ubuntu/workspace/common/middleware/get_company.py", line 47, in process_request
    org = Org.objects.get(id=org_id)
  File "/home/ubuntu/venv/lib/python3.8/site-packages/django/db/models/manager.py", line 85, in manager_method
    return getattr(self.get_queryset(), name)(*args, **kwargs)
  File "/home/ubuntu/venv/lib/python3.8/site-packages/django/db/models/query.py", line 636, in get
    clone = self._chain() if self.query.combinator else self.filter(*args, **kwargs)
  File "/home/ubuntu/venv/lib/python3.8/site-packages/django/db/models/query.py", line 1420, in filter
    return self._filter_or_exclude(False, args, kwargs)
  File "/home/ubuntu/venv/lib/python3.8/site-packages/django/db/models/query.py", line 1438, in _filter_or_exclude
    clone._filter_or_exclude_inplace(negate, args, kwargs)
  File "/home/ubuntu/venv/lib/python3.8/site-packages/django/db/models/query.py", line 1445, in _filter_or_exclude_inplace
    self._query.add_q(Q(*args, **kwargs))
  File "/home/ubuntu/venv/lib/python3.8/site-packages/django/db/models/sql/query.py", line 1532, in add_q
    clause, _ = self._add_q(q_object, self.used_aliases)
  File "/home/ubuntu/venv/lib/python3.8/site-packages/django/db/models/sql/query.py", line 1562, in _add_q
    child_clause, needed_inner = self.build_filter(
  File "/home/ubuntu/venv/lib/python3.8/site-packages/django/db/models/sql/query.py", line 1478, in build_filter
    condition = self.build_lookup(lookups, col, value)
  File "/home/ubuntu/venv/lib/python3.8/site-packages/django/db/models/sql/query.py", line 1303, in build_lookup
    lookup = lookup_class(lhs, rhs)
  File "/home/ubuntu/venv/lib/python3.8/site-packages/django/db/models/lookups.py", line 27, in __init__
    self.rhs = self.get_prep_lookup()
  File "/home/ubuntu/venv/lib/python3.8/site-packages/django/db/models/lookups.py", line 341, in get_prep_lookup
    return super().get_prep_lookup()
  File "/home/ubuntu/venv/lib/python3.8/site-packages/django/db/models/lookups.py", line 85, in get_prep_lookup
    return self.lhs.output_field.get_prep_value(self.rhs)
  File "/home/ubuntu/venv/lib/python3.8/site-packages/django/db/models/fields/__init__.py", line 2020, in get_prep_value
    raise e.__class__(
ValueError: Field 'id' expected a number but got 'null'.
Internal Server Error: /api/users/
Traceback (most recent call last):
  File "/home/ubuntu/venv/lib/python3.8/site-packages/django/db/models/fields/__init__.py", line 2018, in get_prep_value
    return int(value)
ValueError: invalid literal for int() with base 10: 'null'

The above exception was the direct cause of the following exception:

Traceback (most recent call last):
  File "/home/ubuntu/venv/lib/python3.8/site-packages/django/core/handlers/exception.py", line 55, in inner
    response = get_response(request)
  File "/home/ubuntu/workspace/common/middleware/get_company.py", line 35, in __call__
    self.process_request(request)
  File "/home/ubuntu/workspace/common/middleware/get_company.py", line 47, in process_request
    org = Org.objects.get(id=org_id)
  File "/home/ubuntu/venv/lib/python3.8/site-packages/django/db/models/manager.py", line 85, in manager_method
    return getattr(self.get_queryset(), name)(*args, **kwargs)
  File "/home/ubuntu/venv/lib/python3.8/site-packages/django/db/models/query.py", line 636, in get
    clone = self._chain() if self.query.combinator else self.filter(*args, **kwargs)
  File "/home/ubuntu/venv/lib/python3.8/site-packages/django/db/models/query.py", line 1420, in filter
    return self._filter_or_exclude(False, args, kwargs)
  File "/home/ubuntu/venv/lib/python3.8/site-packages/django/db/models/query.py", line 1438, in _filter_or_exclude
    clone._filter_or_exclude_inplace(negate, args, kwargs)
  File "/home/ubuntu/venv/lib/python3.8/site-packages/django/db/models/query.py", line 1445, in _filter_or_exclude_inplace
    self._query.add_q(Q(*args, **kwargs))
  File "/home/ubuntu/venv/lib/python3.8/site-packages/django/db/models/sql/query.py", line 1532, in add_q
    clause, _ = self._add_q(q_object, self.used_aliases)
  File "/home/ubuntu/venv/lib/python3.8/site-packages/django/db/models/sql/query.py", line 1562, in _add_q
    child_clause, needed_inner = self.build_filter(
  File "/home/ubuntu/venv/lib/python3.8/site-packages/django/db/models/sql/query.py", line 1478, in build_filter
    condition = self.build_lookup(lookups, col, value)
  File "/home/ubuntu/venv/lib/python3.8/site-packages/django/db/models/sql/query.py", line 1303, in build_lookup
    lookup = lookup_class(lhs, rhs)
  File "/home/ubuntu/venv/lib/python3.8/site-packages/django/db/models/lookups.py", line 27, in __init__
    self.rhs = self.get_prep_lookup()
  File "/home/ubuntu/venv/lib/python3.8/site-packages/django/db/models/lookups.py", line 341, in get_prep_lookup
    return super().get_prep_lookup()
  File "/home/ubuntu/venv/lib/python3.8/site-packages/django/db/models/lookups.py", line 85, in get_prep_lookup
    return self.lhs.output_field.get_prep_value(self.rhs)
  File "/home/ubuntu/venv/lib/python3.8/site-packages/django/db/models/fields/__init__.py", line 2020, in get_prep_value
    raise e.__class__(
ValueError: Field 'id' expected a number but got 'null'.
/home/ubuntu/workspace/crm/urls.py changed, reloading.
Watching for file changes with StatReloader
Method Not Allowed: /api/auth/register/
Internal Server Error: /api/auth/register/
Traceback (most recent call last):
  File "/home/ubuntu/venv/lib/python3.8/site-packages/kombu/utils/functional.py", line 30, in __call__
    return self.__value__
AttributeError: 'ChannelPromise' object has no attribute '__value__'

During handling of the above exception, another exception occurred:

Traceback (most recent call last):
  File "/home/ubuntu/venv/lib/python3.8/site-packages/kombu/connection.py", line 446, in _reraise_as_library_errors
    yield
  File "/home/ubuntu/venv/lib/python3.8/site-packages/kombu/connection.py", line 433, in _ensure_connection
    return retry_over_time(
  File "/home/ubuntu/venv/lib/python3.8/site-packages/kombu/utils/functional.py", line 312, in retry_over_time
    return fun(*args, **kwargs)
  File "/home/ubuntu/venv/lib/python3.8/site-packages/kombu/connection.py", line 877, in _connection_factory
    self._connection = self._establish_connection()
  File "/home/ubuntu/venv/lib/python3.8/site-packages/kombu/connection.py", line 812, in _establish_connection
    conn = self.transport.establish_connection()
  File "/home/ubuntu/venv/lib/python3.8/site-packages/kombu/transport/pyamqp.py", line 201, in establish_connection
    conn.connect()
  File "/home/ubuntu/venv/lib/python3.8/site-packages/amqp/connection.py", line 323, in connect
    self.transport.connect()
  File "/home/ubuntu/venv/lib/python3.8/site-packages/amqp/transport.py", line 129, in connect
    self._connect(self.host, self.port, self.connect_timeout)
  File "/home/ubuntu/venv/lib/python3.8/site-packages/amqp/transport.py", line 184, in _connect
    self.sock.connect(sa)
ConnectionRefusedError: [Errno 111] Connection refused

The above exception was the direct cause of the following exception:

Traceback (most recent call last):
  File "/home/ubuntu/venv/lib/python3.8/site-packages/django/core/handlers/exception.py", line 55, in inner
    response = get_response(request)
  File "/home/ubuntu/venv/lib/python3.8/site-packages/django/core/handlers/base.py", line 197, in _get_response
    response = wrapped_callback(request, *callback_args, **callback_kwargs)
  File "/home/ubuntu/venv/lib/python3.8/site-packages/django/views/decorators/csrf.py", line 54, in wrapped_view
    return view_func(*args, **kwargs)
  File "/home/ubuntu/venv/lib/python3.8/site-packages/django/views/generic/base.py", line 103, in view
    return self.dispatch(request, *args, **kwargs)
  File "/home/ubuntu/venv/lib/python3.8/site-packages/rest_framework/views.py", line 509, in dispatch
    response = self.handle_exception(exc)
  File "/home/ubuntu/venv/lib/python3.8/site-packages/rest_framework/views.py", line 469, in handle_exception
    self.raise_uncaught_exception(exc)
  File "/home/ubuntu/venv/lib/python3.8/site-packages/rest_framework/views.py", line 480, in raise_uncaught_exception
    raise exc
  File "/home/ubuntu/venv/lib/python3.8/site-packages/rest_framework/views.py", line 506, in dispatch
    response = handler(request, *args, **kwargs)
  File "/home/ubuntu/workspace/common/views.py", line 324, in post
    send_email_to_new_user.delay(
  File "/home/ubuntu/venv/lib/python3.8/site-packages/celery/app/task.py", line 425, in delay
    return self.apply_async(args, kwargs)
  File "/home/ubuntu/venv/lib/python3.8/site-packages/celery/app/task.py", line 575, in apply_async
    return app.send_task(
  File "/home/ubuntu/venv/lib/python3.8/site-packages/celery/app/base.py", line 788, in send_task
    amqp.send_task_message(P, name, message, **options)
  File "/home/ubuntu/venv/lib/python3.8/site-packages/celery/app/amqp.py", line 510, in send_task_message
    ret = producer.publish(
  File "/home/ubuntu/venv/lib/python3.8/site-packages/kombu/messaging.py", line 177, in publish
    return _publish(
  File "/home/ubuntu/venv/lib/python3.8/site-packages/kombu/connection.py", line 523, in _ensured
    return fun(*args, **kwargs)
  File "/home/ubuntu/venv/lib/python3.8/site-packages/kombu/messaging.py", line 186, in _publish
    channel = self.channel
  File "/home/ubuntu/venv/lib/python3.8/site-packages/kombu/messaging.py", line 209, in _get_channel
    channel = self._channel = channel()
  File "/home/ubuntu/venv/lib/python3.8/site-packages/kombu/utils/functional.py", line 32, in __call__
    value = self.__value__ = self.__contract__()
  File "/home/ubuntu/venv/lib/python3.8/site-packages/kombu/messaging.py", line 225, in <lambda>
    channel = ChannelPromise(lambda: connection.default_channel)
  File "/home/ubuntu/venv/lib/python3.8/site-packages/kombu/connection.py", line 895, in default_channel
    self._ensure_connection(**conn_opts)
  File "/home/ubuntu/venv/lib/python3.8/site-packages/kombu/connection.py", line 433, in _ensure_connection
    return retry_over_time(
  File "/usr/lib/python3.8/contextlib.py", line 131, in __exit__
    self.gen.throw(type, value, traceback)
  File "/home/ubuntu/venv/lib/python3.8/site-packages/kombu/connection.py", line 450, in _reraise_as_library_errors
    raise ConnectionError(str(exc)) from exc
kombu.exceptions.OperationalError: [Errno 111] Connection refused
Bad Request: /api/auth/login/
Bad Request: /api/auth/login/
Bad Request: /api/auth/login/
Unsupported Media Type: /api/auth/register/
Unsupported Media Type: /api/auth/register/
Internal Server Error: /api/auth/register/
Traceback (most recent call last):
  File "/home/ubuntu/venv/lib/python3.8/site-packages/kombu/utils/functional.py", line 30, in __call__
    return self.__value__
AttributeError: 'ChannelPromise' object has no attribute '__value__'

During handling of the above exception, another exception occurred:

Traceback (most recent call last):
  File "/home/ubuntu/venv/lib/python3.8/site-packages/kombu/connection.py", line 446, in _reraise_as_library_errors
    yield
  File "/home/ubuntu/venv/lib/python3.8/site-packages/kombu/connection.py", line 433, in _ensure_connection
    return retry_over_time(
  File "/home/ubuntu/venv/lib/python3.8/site-packages/kombu/utils/functional.py", line 312, in retry_over_time
    return fun(*args, **kwargs)
  File "/home/ubuntu/venv/lib/python3.8/site-packages/kombu/connection.py", line 877, in _connection_factory
    self._connection = self._establish_connection()
  File "/home/ubuntu/venv/lib/python3.8/site-packages/kombu/connection.py", line 812, in _establish_connection
    conn = self.transport.establish_connection()
  File "/home/ubuntu/venv/lib/python3.8/site-packages/kombu/transport/pyamqp.py", line 201, in establish_connection
    conn.connect()
  File "/home/ubuntu/venv/lib/python3.8/site-packages/amqp/connection.py", line 323, in connect
    self.transport.connect()
  File "/home/ubuntu/venv/lib/python3.8/site-packages/amqp/transport.py", line 129, in connect
    self._connect(self.host, self.port, self.connect_timeout)
  File "/home/ubuntu/venv/lib/python3.8/site-packages/amqp/transport.py", line 184, in _connect
    self.sock.connect(sa)
ConnectionRefusedError: [Errno 111] Connection refused

The above exception was the direct cause of the following exception:

Traceback (most recent call last):
  File "/home/ubuntu/venv/lib/python3.8/site-packages/django/core/handlers/exception.py", line 55, in inner
    response = get_response(request)
  File "/home/ubuntu/venv/lib/python3.8/site-packages/django/core/handlers/base.py", line 197, in _get_response
    response = wrapped_callback(request, *callback_args, **callback_kwargs)
  File "/home/ubuntu/venv/lib/python3.8/site-packages/django/views/decorators/csrf.py", line 54, in wrapped_view
    return view_func(*args, **kwargs)
  File "/home/ubuntu/venv/lib/python3.8/site-packages/django/views/generic/base.py", line 103, in view
    return self.dispatch(request, *args, **kwargs)
  File "/home/ubuntu/venv/lib/python3.8/site-packages/rest_framework/views.py", line 509, in dispatch
    response = self.handle_exception(exc)
  File "/home/ubuntu/venv/lib/python3.8/site-packages/rest_framework/views.py", line 469, in handle_exception
    self.raise_uncaught_exception(exc)
  File "/home/ubuntu/venv/lib/python3.8/site-packages/rest_framework/views.py", line 480, in raise_uncaught_exception
    raise exc
  File "/home/ubuntu/venv/lib/python3.8/site-packages/rest_framework/views.py", line 506, in dispatch
    response = handler(request, *args, **kwargs)
  File "/home/ubuntu/workspace/common/views.py", line 324, in post
    send_email_to_new_user.delay(
  File "/home/ubuntu/venv/lib/python3.8/site-packages/celery/app/task.py", line 425, in delay
    return self.apply_async(args, kwargs)
  File "/home/ubuntu/venv/lib/python3.8/site-packages/celery/app/task.py", line 575, in apply_async
    return app.send_task(
  File "/home/ubuntu/venv/lib/python3.8/site-packages/celery/app/base.py", line 788, in send_task
    amqp.send_task_message(P, name, message, **options)
  File "/home/ubuntu/venv/lib/python3.8/site-packages/celery/app/amqp.py", line 510, in send_task_message
    ret = producer.publish(
  File "/home/ubuntu/venv/lib/python3.8/site-packages/kombu/messaging.py", line 177, in publish
    return _publish(
  File "/home/ubuntu/venv/lib/python3.8/site-packages/kombu/connection.py", line 523, in _ensured
    return fun(*args, **kwargs)
  File "/home/ubuntu/venv/lib/python3.8/site-packages/kombu/messaging.py", line 186, in _publish
    channel = self.channel
  File "/home/ubuntu/venv/lib/python3.8/site-packages/kombu/messaging.py", line 209, in _get_channel
    channel = self._channel = channel()
  File "/home/ubuntu/venv/lib/python3.8/site-packages/kombu/utils/functional.py", line 32, in __call__
    value = self.__value__ = self.__contract__()
  File "/home/ubuntu/venv/lib/python3.8/site-packages/kombu/messaging.py", line 225, in <lambda>
    channel = ChannelPromise(lambda: connection.default_channel)
  File "/home/ubuntu/venv/lib/python3.8/site-packages/kombu/connection.py", line 895, in default_channel
    self._ensure_connection(**conn_opts)
  File "/home/ubuntu/venv/lib/python3.8/site-packages/kombu/connection.py", line 433, in _ensure_connection
    return retry_over_time(
  File "/usr/lib/python3.8/contextlib.py", line 131, in __exit__
    self.gen.throw(type, value, traceback)
  File "/home/ubuntu/venv/lib/python3.8/site-packages/kombu/connection.py", line 450, in _reraise_as_library_errors
    raise ConnectionError(str(exc)) from exc
kombu.exceptions.OperationalError: [Errno 111] Connection refused
Unauthorized: /api/auth/create-org/
Unauthorized: /api/auth/create-org/
Internal Server Error: /api/auth/create-org/
Traceback (most recent call last):
  File "/home/ubuntu/venv/lib/python3.8/site-packages/django/db/backends/utils.py", line 89, in _execute
    return self.cursor.execute(sql, params)
psycopg2.errors.StringDataRightTruncation: value too long for type character varying(3)


The above exception was the direct cause of the following exception:

Traceback (most recent call last):
  File "/home/ubuntu/venv/lib/python3.8/site-packages/django/core/handlers/exception.py", line 55, in inner
    response = get_response(request)
  File "/home/ubuntu/venv/lib/python3.8/site-packages/django/core/handlers/base.py", line 197, in _get_response
    response = wrapped_callback(request, *callback_args, **callback_kwargs)
  File "/home/ubuntu/venv/lib/python3.8/site-packages/django/views/decorators/csrf.py", line 54, in wrapped_view
    return view_func(*args, **kwargs)
  File "/home/ubuntu/venv/lib/python3.8/site-packages/django/views/generic/base.py", line 103, in view
    return self.dispatch(request, *args, **kwargs)
  File "/home/ubuntu/venv/lib/python3.8/site-packages/rest_framework/views.py", line 509, in dispatch
    response = self.handle_exception(exc)
  File "/home/ubuntu/venv/lib/python3.8/site-packages/rest_framework/views.py", line 469, in handle_exception
    self.raise_uncaught_exception(exc)
  File "/home/ubuntu/venv/lib/python3.8/site-packages/rest_framework/views.py", line 480, in raise_uncaught_exception
    raise exc
  File "/home/ubuntu/venv/lib/python3.8/site-packages/rest_framework/views.py", line 506, in dispatch
    response = handler(request, *args, **kwargs)
  File "/home/ubuntu/workspace/common/views.py", line 358, in post
    org_obj = serializer.save()
  File "/home/ubuntu/venv/lib/python3.8/site-packages/rest_framework/serializers.py", line 212, in save
    self.instance = self.create(validated_data)
  File "/home/ubuntu/venv/lib/python3.8/site-packages/rest_framework/serializers.py", line 962, in create
    instance = ModelClass._default_manager.create(**validated_data)
  File "/home/ubuntu/venv/lib/python3.8/site-packages/django/db/models/manager.py", line 85, in manager_method
    return getattr(self.get_queryset(), name)(*args, **kwargs)
  File "/home/ubuntu/venv/lib/python3.8/site-packages/django/db/models/query.py", line 671, in create
    obj.save(force_insert=True, using=self.db)
  File "/home/ubuntu/venv/lib/python3.8/site-packages/django/db/models/base.py", line 831, in save
    self.save_base(
  File "/home/ubuntu/venv/lib/python3.8/site-packages/django/db/models/base.py", line 882, in save_base
    updated = self._save_table(
  File "/home/ubuntu/venv/lib/python3.8/site-packages/django/db/models/base.py", line 1025, in _save_table
    results = self._do_insert(
  File "/home/ubuntu/venv/lib/python3.8/site-packages/django/db/models/base.py", line 1066, in _do_insert
    return manager._insert(
  File "/home/ubuntu/venv/lib/python3.8/site-packages/django/db/models/manager.py", line 85, in manager_method
    return getattr(self.get_queryset(), name)(*args, **kwargs)
  File "/home/ubuntu/venv/lib/python3.8/site-packages/django/db/models/query.py", line 1790, in _insert
    return query.get_compiler(using=using).execute_sql(returning_fields)
  File "/home/ubuntu/venv/lib/python3.8/site-packages/django/db/models/sql/compiler.py", line 1657, in execute_sql
    cursor.execute(sql, params)
  File "/home/ubuntu/venv/lib/python3.8/site-packages/django/db/backends/utils.py", line 103, in execute
    return super().execute(sql, params)
  File "/home/ubuntu/venv/lib/python3.8/site-packages/django/db/backends/utils.py", line 67, in execute
    return self._execute_with_wrappers(
  File "/home/ubuntu/venv/lib/python3.8/site-packages/django/db/backends/utils.py", line 80, in _execute_with_wrappers
    return executor(sql, params, many, context)
  File "/home/ubuntu/venv/lib/python3.8/site-packages/django/db/backends/utils.py", line 89, in _execute
    return self.cursor.execute(sql, params)
  File "/home/ubuntu/venv/lib/python3.8/site-packages/django/db/utils.py", line 91, in __exit__
    raise dj_exc_value.with_traceback(traceback) from exc_value
  File "/home/ubuntu/venv/lib/python3.8/site-packages/django/db/backends/utils.py", line 89, in _execute
    return self.cursor.execute(sql, params)
django.db.utils.DataError: value too long for type character varying(3)

Bad Request: /api/auth/login/
Internal Server Error: /api/leads/
Traceback (most recent call last):
  File "/home/ubuntu/venv/lib/python3.8/site-packages/django/db/models/fields/__init__.py", line 2018, in get_prep_value
    return int(value)
ValueError: invalid literal for int() with base 10: 'null'

The above exception was the direct cause of the following exception:

Traceback (most recent call last):
  File "/home/ubuntu/venv/lib/python3.8/site-packages/django/core/handlers/exception.py", line 55, in inner
    response = get_response(request)
  File "/home/ubuntu/workspace/common/middleware/get_company.py", line 35, in __call__
    self.process_request(request)
  File "/home/ubuntu/workspace/common/middleware/get_company.py", line 47, in process_request
    org = Org.objects.get(id=org_id)
  File "/home/ubuntu/venv/lib/python3.8/site-packages/django/db/models/manager.py", line 85, in manager_method
    return getattr(self.get_queryset(), name)(*args, **kwargs)
  File "/home/ubuntu/venv/lib/python3.8/site-packages/django/db/models/query.py", line 636, in get
    clone = self._chain() if self.query.combinator else self.filter(*args, **kwargs)
  File "/home/ubuntu/venv/lib/python3.8/site-packages/django/db/models/query.py", line 1420, in filter
    return self._filter_or_exclude(False, args, kwargs)
  File "/home/ubuntu/venv/lib/python3.8/site-packages/django/db/models/query.py", line 1438, in _filter_or_exclude
    clone._filter_or_exclude_inplace(negate, args, kwargs)
  File "/home/ubuntu/venv/lib/python3.8/site-packages/django/db/models/query.py", line 1445, in _filter_or_exclude_inplace
    self._query.add_q(Q(*args, **kwargs))
  File "/home/ubuntu/venv/lib/python3.8/site-packages/django/db/models/sql/query.py", line 1532, in add_q
    clause, _ = self._add_q(q_object, self.used_aliases)
  File "/home/ubuntu/venv/lib/python3.8/site-packages/django/db/models/sql/query.py", line 1562, in _add_q
    child_clause, needed_inner = self.build_filter(
  File "/home/ubuntu/venv/lib/python3.8/site-packages/django/db/models/sql/query.py", line 1478, in build_filter
    condition = self.build_lookup(lookups, col, value)
  File "/home/ubuntu/venv/lib/python3.8/site-packages/django/db/models/sql/query.py", line 1303, in build_lookup
    lookup = lookup_class(lhs, rhs)
  File "/home/ubuntu/venv/lib/python3.8/site-packages/django/db/models/lookups.py", line 27, in __init__
    self.rhs = self.get_prep_lookup()
  File "/home/ubuntu/venv/lib/python3.8/site-packages/django/db/models/lookups.py", line 341, in get_prep_lookup
    return super().get_prep_lookup()
  File "/home/ubuntu/venv/lib/python3.8/site-packages/django/db/models/lookups.py", line 85, in get_prep_lookup
    return self.lhs.output_field.get_prep_value(self.rhs)
  File "/home/ubuntu/venv/lib/python3.8/site-packages/django/db/models/fields/__init__.py", line 2020, in get_prep_value
    raise e.__class__(
ValueError: Field 'id' expected a number but got 'null'.
Internal Server Error: /api/users/
Traceback (most recent call last):
  File "/home/ubuntu/venv/lib/python3.8/site-packages/django/db/models/fields/__init__.py", line 2018, in get_prep_value
    return int(value)
ValueError: invalid literal for int() with base 10: 'null'

The above exception was the direct cause of the following exception:

Traceback (most recent call last):
  File "/home/ubuntu/venv/lib/python3.8/site-packages/django/core/handlers/exception.py", line 55, in inner
    response = get_response(request)
  File "/home/ubuntu/workspace/common/middleware/get_company.py", line 35, in __call__
    self.process_request(request)
  File "/home/ubuntu/workspace/common/middleware/get_company.py", line 47, in process_request
    org = Org.objects.get(id=org_id)
  File "/home/ubuntu/venv/lib/python3.8/site-packages/django/db/models/manager.py", line 85, in manager_method
    return getattr(self.get_queryset(), name)(*args, **kwargs)
  File "/home/ubuntu/venv/lib/python3.8/site-packages/django/db/models/query.py", line 636, in get
    clone = self._chain() if self.query.combinator else self.filter(*args, **kwargs)
  File "/home/ubuntu/venv/lib/python3.8/site-packages/django/db/models/query.py", line 1420, in filter
    return self._filter_or_exclude(False, args, kwargs)
  File "/home/ubuntu/venv/lib/python3.8/site-packages/django/db/models/query.py", line 1438, in _filter_or_exclude
    clone._filter_or_exclude_inplace(negate, args, kwargs)
  File "/home/ubuntu/venv/lib/python3.8/site-packages/django/db/models/query.py", line 1445, in _filter_or_exclude_inplace
    self._query.add_q(Q(*args, **kwargs))
  File "/home/ubuntu/venv/lib/python3.8/site-packages/django/db/models/sql/query.py", line 1532, in add_q
    clause, _ = self._add_q(q_object, self.used_aliases)
  File "/home/ubuntu/venv/lib/python3.8/site-packages/django/db/models/sql/query.py", line 1562, in _add_q
    child_clause, needed_inner = self.build_filter(
  File "/home/ubuntu/venv/lib/python3.8/site-packages/django/db/models/sql/query.py", line 1478, in build_filter
    condition = self.build_lookup(lookups, col, value)
  File "/home/ubuntu/venv/lib/python3.8/site-packages/django/db/models/sql/query.py", line 1303, in build_lookup
    lookup = lookup_class(lhs, rhs)
  File "/home/ubuntu/venv/lib/python3.8/site-packages/django/db/models/lookups.py", line 27, in __init__
    self.rhs = self.get_prep_lookup()
  File "/home/ubuntu/venv/lib/python3.8/site-packages/django/db/models/lookups.py", line 341, in get_prep_lookup
    return super().get_prep_lookup()
  File "/home/ubuntu/venv/lib/python3.8/site-packages/django/db/models/lookups.py", line 85, in get_prep_lookup
    return self.lhs.output_field.get_prep_value(self.rhs)
  File "/home/ubuntu/venv/lib/python3.8/site-packages/django/db/models/fields/__init__.py", line 2020, in get_prep_value
    raise e.__class__(
ValueError: Field 'id' expected a number but got 'null'.
Internal Server Error: /api/leads/
Traceback (most recent call last):
  File "/home/ubuntu/venv/lib/python3.8/site-packages/django/db/models/fields/__init__.py", line 2018, in get_prep_value
    return int(value)
ValueError: invalid literal for int() with base 10: 'null'

The above exception was the direct cause of the following exception:

Traceback (most recent call last):
  File "/home/ubuntu/venv/lib/python3.8/site-packages/django/core/handlers/exception.py", line 55, in inner
    response = get_response(request)
  File "/home/ubuntu/workspace/common/middleware/get_company.py", line 35, in __call__
    self.process_request(request)
  File "/home/ubuntu/workspace/common/middleware/get_company.py", line 47, in process_request
    org = Org.objects.get(id=org_id)
  File "/home/ubuntu/venv/lib/python3.8/site-packages/django/db/models/manager.py", line 85, in manager_method
    return getattr(self.get_queryset(), name)(*args, **kwargs)
  File "/home/ubuntu/venv/lib/python3.8/site-packages/django/db/models/query.py", line 636, in get
    clone = self._chain() if self.query.combinator else self.filter(*args, **kwargs)
  File "/home/ubuntu/venv/lib/python3.8/site-packages/django/db/models/query.py", line 1420, in filter
    return self._filter_or_exclude(False, args, kwargs)
  File "/home/ubuntu/venv/lib/python3.8/site-packages/django/db/models/query.py", line 1438, in _filter_or_exclude
    clone._filter_or_exclude_inplace(negate, args, kwargs)
  File "/home/ubuntu/venv/lib/python3.8/site-packages/django/db/models/query.py", line 1445, in _filter_or_exclude_inplace
    self._query.add_q(Q(*args, **kwargs))
  File "/home/ubuntu/venv/lib/python3.8/site-packages/django/db/models/sql/query.py", line 1532, in add_q
    clause, _ = self._add_q(q_object, self.used_aliases)
  File "/home/ubuntu/venv/lib/python3.8/site-packages/django/db/models/sql/query.py", line 1562, in _add_q
    child_clause, needed_inner = self.build_filter(
  File "/home/ubuntu/venv/lib/python3.8/site-packages/django/db/models/sql/query.py", line 1478, in build_filter
    condition = self.build_lookup(lookups, col, value)
  File "/home/ubuntu/venv/lib/python3.8/site-packages/django/db/models/sql/query.py", line 1303, in build_lookup
    lookup = lookup_class(lhs, rhs)
  File "/home/ubuntu/venv/lib/python3.8/site-packages/django/db/models/lookups.py", line 27, in __init__
    self.rhs = self.get_prep_lookup()
  File "/home/ubuntu/venv/lib/python3.8/site-packages/django/db/models/lookups.py", line 341, in get_prep_lookup
    return super().get_prep_lookup()
  File "/home/ubuntu/venv/lib/python3.8/site-packages/django/db/models/lookups.py", line 85, in get_prep_lookup
    return self.lhs.output_field.get_prep_value(self.rhs)
  File "/home/ubuntu/venv/lib/python3.8/site-packages/django/db/models/fields/__init__.py", line 2020, in get_prep_value
    raise e.__class__(
ValueError: Field 'id' expected a number but got 'null'.
Internal Server Error: /api/leads/
Traceback (most recent call last):
  File "/home/ubuntu/venv/lib/python3.8/site-packages/django/db/models/fields/__init__.py", line 2018, in get_prep_value
    return int(value)
ValueError: invalid literal for int() with base 10: 'ALNafi'

The above exception was the direct cause of the following exception:

Traceback (most recent call last):
  File "/home/ubuntu/venv/lib/python3.8/site-packages/django/core/handlers/exception.py", line 55, in inner
    response = get_response(request)
  File "/home/ubuntu/workspace/common/middleware/get_company.py", line 35, in __call__
    self.process_request(request)
  File "/home/ubuntu/workspace/common/middleware/get_company.py", line 47, in process_request
    org = Org.objects.get(id=org_id)
  File "/home/ubuntu/venv/lib/python3.8/site-packages/django/db/models/manager.py", line 85, in manager_method
    return getattr(self.get_queryset(), name)(*args, **kwargs)
  File "/home/ubuntu/venv/lib/python3.8/site-packages/django/db/models/query.py", line 636, in get
    clone = self._chain() if self.query.combinator else self.filter(*args, **kwargs)
  File "/home/ubuntu/venv/lib/python3.8/site-packages/django/db/models/query.py", line 1420, in filter
    return self._filter_or_exclude(False, args, kwargs)
  File "/home/ubuntu/venv/lib/python3.8/site-packages/django/db/models/query.py", line 1438, in _filter_or_exclude
    clone._filter_or_exclude_inplace(negate, args, kwargs)
  File "/home/ubuntu/venv/lib/python3.8/site-packages/django/db/models/query.py", line 1445, in _filter_or_exclude_inplace
    self._query.add_q(Q(*args, **kwargs))
  File "/home/ubuntu/venv/lib/python3.8/site-packages/django/db/models/sql/query.py", line 1532, in add_q
    clause, _ = self._add_q(q_object, self.used_aliases)
  File "/home/ubuntu/venv/lib/python3.8/site-packages/django/db/models/sql/query.py", line 1562, in _add_q
    child_clause, needed_inner = self.build_filter(
  File "/home/ubuntu/venv/lib/python3.8/site-packages/django/db/models/sql/query.py", line 1478, in build_filter
    condition = self.build_lookup(lookups, col, value)
  File "/home/ubuntu/venv/lib/python3.8/site-packages/django/db/models/sql/query.py", line 1303, in build_lookup
    lookup = lookup_class(lhs, rhs)
  File "/home/ubuntu/venv/lib/python3.8/site-packages/django/db/models/lookups.py", line 27, in __init__
    self.rhs = self.get_prep_lookup()
  File "/home/ubuntu/venv/lib/python3.8/site-packages/django/db/models/lookups.py", line 341, in get_prep_lookup
    return super().get_prep_lookup()
  File "/home/ubuntu/venv/lib/python3.8/site-packages/django/db/models/lookups.py", line 85, in get_prep_lookup
    return self.lhs.output_field.get_prep_value(self.rhs)
  File "/home/ubuntu/venv/lib/python3.8/site-packages/django/db/models/fields/__init__.py", line 2020, in get_prep_value
    raise e.__class__(
ValueError: Field 'id' expected a number but got 'ALNafi'.
Internal Server Error: /api/accounts/
Traceback (most recent call last):
  File "/home/ubuntu/venv/lib/python3.8/site-packages/django/db/models/fields/__init__.py", line 2018, in get_prep_value
    return int(value)
ValueError: invalid literal for int() with base 10: 'ALNafi'

The above exception was the direct cause of the following exception:

Traceback (most recent call last):
  File "/home/ubuntu/venv/lib/python3.8/site-packages/django/core/handlers/exception.py", line 55, in inner
    response = get_response(request)
  File "/home/ubuntu/workspace/common/middleware/get_company.py", line 35, in __call__
    self.process_request(request)
  File "/home/ubuntu/workspace/common/middleware/get_company.py", line 47, in process_request
    org = Org.objects.get(id=org_id)
  File "/home/ubuntu/venv/lib/python3.8/site-packages/django/db/models/manager.py", line 85, in manager_method
    return getattr(self.get_queryset(), name)(*args, **kwargs)
  File "/home/ubuntu/venv/lib/python3.8/site-packages/django/db/models/query.py", line 636, in get
    clone = self._chain() if self.query.combinator else self.filter(*args, **kwargs)
  File "/home/ubuntu/venv/lib/python3.8/site-packages/django/db/models/query.py", line 1420, in filter
    return self._filter_or_exclude(False, args, kwargs)
  File "/home/ubuntu/venv/lib/python3.8/site-packages/django/db/models/query.py", line 1438, in _filter_or_exclude
    clone._filter_or_exclude_inplace(negate, args, kwargs)
  File "/home/ubuntu/venv/lib/python3.8/site-packages/django/db/models/query.py", line 1445, in _filter_or_exclude_inplace
    self._query.add_q(Q(*args, **kwargs))
  File "/home/ubuntu/venv/lib/python3.8/site-packages/django/db/models/sql/query.py", line 1532, in add_q
    clause, _ = self._add_q(q_object, self.used_aliases)
  File "/home/ubuntu/venv/lib/python3.8/site-packages/django/db/models/sql/query.py", line 1562, in _add_q
    child_clause, needed_inner = self.build_filter(
  File "/home/ubuntu/venv/lib/python3.8/site-packages/django/db/models/sql/query.py", line 1478, in build_filter
    condition = self.build_lookup(lookups, col, value)
  File "/home/ubuntu/venv/lib/python3.8/site-packages/django/db/models/sql/query.py", line 1303, in build_lookup
    lookup = lookup_class(lhs, rhs)
  File "/home/ubuntu/venv/lib/python3.8/site-packages/django/db/models/lookups.py", line 27, in __init__
    self.rhs = self.get_prep_lookup()
  File "/home/ubuntu/venv/lib/python3.8/site-packages/django/db/models/lookups.py", line 341, in get_prep_lookup
    return super().get_prep_lookup()
  File "/home/ubuntu/venv/lib/python3.8/site-packages/django/db/models/lookups.py", line 85, in get_prep_lookup
    return self.lhs.output_field.get_prep_value(self.rhs)
  File "/home/ubuntu/venv/lib/python3.8/site-packages/django/db/models/fields/__init__.py", line 2020, in get_prep_value
    raise e.__class__(
ValueError: Field 'id' expected a number but got 'ALNafi'.
Internal Server Error: /api/users/
Traceback (most recent call last):
  File "/home/ubuntu/venv/lib/python3.8/site-packages/django/db/models/fields/__init__.py", line 2018, in get_prep_value
    return int(value)
ValueError: invalid literal for int() with base 10: 'ALNafi'

The above exception was the direct cause of the following exception:

Traceback (most recent call last):
  File "/home/ubuntu/venv/lib/python3.8/site-packages/django/core/handlers/exception.py", line 55, in inner
    response = get_response(request)
  File "/home/ubuntu/workspace/common/middleware/get_company.py", line 35, in __call__
    self.process_request(request)
  File "/home/ubuntu/workspace/common/middleware/get_company.py", line 47, in process_request
    org = Org.objects.get(id=org_id)
  File "/home/ubuntu/venv/lib/python3.8/site-packages/django/db/models/manager.py", line 85, in manager_method
    return getattr(self.get_queryset(), name)(*args, **kwargs)
  File "/home/ubuntu/venv/lib/python3.8/site-packages/django/db/models/query.py", line 636, in get
    clone = self._chain() if self.query.combinator else self.filter(*args, **kwargs)
  File "/home/ubuntu/venv/lib/python3.8/site-packages/django/db/models/query.py", line 1420, in filter
    return self._filter_or_exclude(False, args, kwargs)
  File "/home/ubuntu/venv/lib/python3.8/site-packages/django/db/models/query.py", line 1438, in _filter_or_exclude
    clone._filter_or_exclude_inplace(negate, args, kwargs)
  File "/home/ubuntu/venv/lib/python3.8/site-packages/django/db/models/query.py", line 1445, in _filter_or_exclude_inplace
    self._query.add_q(Q(*args, **kwargs))
  File "/home/ubuntu/venv/lib/python3.8/site-packages/django/db/models/sql/query.py", line 1532, in add_q
    clause, _ = self._add_q(q_object, self.used_aliases)
  File "/home/ubuntu/venv/lib/python3.8/site-packages/django/db/models/sql/query.py", line 1562, in _add_q
    child_clause, needed_inner = self.build_filter(
  File "/home/ubuntu/venv/lib/python3.8/site-packages/django/db/models/sql/query.py", line 1478, in build_filter
    condition = self.build_lookup(lookups, col, value)
  File "/home/ubuntu/venv/lib/python3.8/site-packages/django/db/models/sql/query.py", line 1303, in build_lookup
    lookup = lookup_class(lhs, rhs)
  File "/home/ubuntu/venv/lib/python3.8/site-packages/django/db/models/lookups.py", line 27, in __init__
    self.rhs = self.get_prep_lookup()
  File "/home/ubuntu/venv/lib/python3.8/site-packages/django/db/models/lookups.py", line 341, in get_prep_lookup
    return super().get_prep_lookup()
  File "/home/ubuntu/venv/lib/python3.8/site-packages/django/db/models/lookups.py", line 85, in get_prep_lookup
    return self.lhs.output_field.get_prep_value(self.rhs)
  File "/home/ubuntu/venv/lib/python3.8/site-packages/django/db/models/fields/__init__.py", line 2020, in get_prep_value
    raise e.__class__(
ValueError: Field 'id' expected a number but got 'ALNafi'.
Internal Server Error: /api/leads/
Traceback (most recent call last):
  File "/home/ubuntu/venv/lib/python3.8/site-packages/django/db/models/fields/__init__.py", line 2018, in get_prep_value
    return int(value)
ValueError: invalid literal for int() with base 10: 'ALNafi'

The above exception was the direct cause of the following exception:

Traceback (most recent call last):
  File "/home/ubuntu/venv/lib/python3.8/site-packages/django/core/handlers/exception.py", line 55, in inner
    response = get_response(request)
  File "/home/ubuntu/workspace/common/middleware/get_company.py", line 35, in __call__
    self.process_request(request)
  File "/home/ubuntu/workspace/common/middleware/get_company.py", line 47, in process_request
    org = Org.objects.get(id=org_id)
  File "/home/ubuntu/venv/lib/python3.8/site-packages/django/db/models/manager.py", line 85, in manager_method
    return getattr(self.get_queryset(), name)(*args, **kwargs)
  File "/home/ubuntu/venv/lib/python3.8/site-packages/django/db/models/query.py", line 636, in get
    clone = self._chain() if self.query.combinator else self.filter(*args, **kwargs)
  File "/home/ubuntu/venv/lib/python3.8/site-packages/django/db/models/query.py", line 1420, in filter
    return self._filter_or_exclude(False, args, kwargs)
  File "/home/ubuntu/venv/lib/python3.8/site-packages/django/db/models/query.py", line 1438, in _filter_or_exclude
    clone._filter_or_exclude_inplace(negate, args, kwargs)
  File "/home/ubuntu/venv/lib/python3.8/site-packages/django/db/models/query.py", line 1445, in _filter_or_exclude_inplace
    self._query.add_q(Q(*args, **kwargs))
  File "/home/ubuntu/venv/lib/python3.8/site-packages/django/db/models/sql/query.py", line 1532, in add_q
    clause, _ = self._add_q(q_object, self.used_aliases)
  File "/home/ubuntu/venv/lib/python3.8/site-packages/django/db/models/sql/query.py", line 1562, in _add_q
    child_clause, needed_inner = self.build_filter(
  File "/home/ubuntu/venv/lib/python3.8/site-packages/django/db/models/sql/query.py", line 1478, in build_filter
    condition = self.build_lookup(lookups, col, value)
  File "/home/ubuntu/venv/lib/python3.8/site-packages/django/db/models/sql/query.py", line 1303, in build_lookup
    lookup = lookup_class(lhs, rhs)
  File "/home/ubuntu/venv/lib/python3.8/site-packages/django/db/models/lookups.py", line 27, in __init__
    self.rhs = self.get_prep_lookup()
  File "/home/ubuntu/venv/lib/python3.8/site-packages/django/db/models/lookups.py", line 341, in get_prep_lookup
    return super().get_prep_lookup()
  File "/home/ubuntu/venv/lib/python3.8/site-packages/django/db/models/lookups.py", line 85, in get_prep_lookup
    return self.lhs.output_field.get_prep_value(self.rhs)
  File "/home/ubuntu/venv/lib/python3.8/site-packages/django/db/models/fields/__init__.py", line 2020, in get_prep_value
    raise e.__class__(
ValueError: Field 'id' expected a number but got 'ALNafi'.
Internal Server Error: /api/accounts/
Traceback (most recent call last):
  File "/home/ubuntu/venv/lib/python3.8/site-packages/django/db/models/fields/__init__.py", line 2018, in get_prep_value
    return int(value)
ValueError: invalid literal for int() with base 10: 'ALNafi'

The above exception was the direct cause of the following exception:

Traceback (most recent call last):
  File "/home/ubuntu/venv/lib/python3.8/site-packages/django/core/handlers/exception.py", line 55, in inner
    response = get_response(request)
  File "/home/ubuntu/workspace/common/middleware/get_company.py", line 35, in __call__
    self.process_request(request)
  File "/home/ubuntu/workspace/common/middleware/get_company.py", line 47, in process_request
    org = Org.objects.get(id=org_id)
  File "/home/ubuntu/venv/lib/python3.8/site-packages/django/db/models/manager.py", line 85, in manager_method
    return getattr(self.get_queryset(), name)(*args, **kwargs)
  File "/home/ubuntu/venv/lib/python3.8/site-packages/django/db/models/query.py", line 636, in get
    clone = self._chain() if self.query.combinator else self.filter(*args, **kwargs)
  File "/home/ubuntu/venv/lib/python3.8/site-packages/django/db/models/query.py", line 1420, in filter
    return self._filter_or_exclude(False, args, kwargs)
  File "/home/ubuntu/venv/lib/python3.8/site-packages/django/db/models/query.py", line 1438, in _filter_or_exclude
    clone._filter_or_exclude_inplace(negate, args, kwargs)
  File "/home/ubuntu/venv/lib/python3.8/site-packages/django/db/models/query.py", line 1445, in _filter_or_exclude_inplace
    self._query.add_q(Q(*args, **kwargs))
  File "/home/ubuntu/venv/lib/python3.8/site-packages/django/db/models/sql/query.py", line 1532, in add_q
    clause, _ = self._add_q(q_object, self.used_aliases)
  File "/home/ubuntu/venv/lib/python3.8/site-packages/django/db/models/sql/query.py", line 1562, in _add_q
    child_clause, needed_inner = self.build_filter(
  File "/home/ubuntu/venv/lib/python3.8/site-packages/django/db/models/sql/query.py", line 1478, in build_filter
    condition = self.build_lookup(lookups, col, value)
  File "/home/ubuntu/venv/lib/python3.8/site-packages/django/db/models/sql/query.py", line 1303, in build_lookup
    lookup = lookup_class(lhs, rhs)
  File "/home/ubuntu/venv/lib/python3.8/site-packages/django/db/models/lookups.py", line 27, in __init__
    self.rhs = self.get_prep_lookup()
  File "/home/ubuntu/venv/lib/python3.8/site-packages/django/db/models/lookups.py", line 341, in get_prep_lookup
    return super().get_prep_lookup()
  File "/home/ubuntu/venv/lib/python3.8/site-packages/django/db/models/lookups.py", line 85, in get_prep_lookup
    return self.lhs.output_field.get_prep_value(self.rhs)
  File "/home/ubuntu/venv/lib/python3.8/site-packages/django/db/models/fields/__init__.py", line 2020, in get_prep_value
    raise e.__class__(
ValueError: Field 'id' expected a number but got 'ALNafi'.
Internal Server Error: /api/accounts/
Traceback (most recent call last):
  File "/home/ubuntu/venv/lib/python3.8/site-packages/django/core/handlers/exception.py", line 55, in inner
    response = get_response(request)
  File "/home/ubuntu/workspace/common/middleware/get_company.py", line 35, in __call__
    self.process_request(request)
  File "/home/ubuntu/workspace/common/middleware/get_company.py", line 47, in process_request
    org = Org.objects.get(id=org_id)
  File "/home/ubuntu/venv/lib/python3.8/site-packages/django/db/models/manager.py", line 85, in manager_method
    return getattr(self.get_queryset(), name)(*args, **kwargs)
  File "/home/ubuntu/venv/lib/python3.8/site-packages/django/db/models/query.py", line 650, in get
    raise self.model.DoesNotExist(
common.models.Org.DoesNotExist: Org matching query does not exist.
Internal Server Error: /api/auth/create-org/
Traceback (most recent call last):
  File "/home/ubuntu/venv/lib/python3.8/site-packages/django/db/backends/utils.py", line 89, in _execute
    return self.cursor.execute(sql, params)
psycopg2.errors.StringDataRightTruncation: value too long for type character varying(3)


The above exception was the direct cause of the following exception:

Traceback (most recent call last):
  File "/home/ubuntu/venv/lib/python3.8/site-packages/django/core/handlers/exception.py", line 55, in inner
    response = get_response(request)
  File "/home/ubuntu/venv/lib/python3.8/site-packages/django/core/handlers/base.py", line 197, in _get_response
    response = wrapped_callback(request, *callback_args, **callback_kwargs)
  File "/home/ubuntu/venv/lib/python3.8/site-packages/django/views/decorators/csrf.py", line 54, in wrapped_view
    return view_func(*args, **kwargs)
  File "/home/ubuntu/venv/lib/python3.8/site-packages/django/views/generic/base.py", line 103, in view
    return self.dispatch(request, *args, **kwargs)
  File "/home/ubuntu/venv/lib/python3.8/site-packages/rest_framework/views.py", line 509, in dispatch
    response = self.handle_exception(exc)
  File "/home/ubuntu/venv/lib/python3.8/site-packages/rest_framework/views.py", line 469, in handle_exception
    self.raise_uncaught_exception(exc)
  File "/home/ubuntu/venv/lib/python3.8/site-packages/rest_framework/views.py", line 480, in raise_uncaught_exception
    raise exc
  File "/home/ubuntu/venv/lib/python3.8/site-packages/rest_framework/views.py", line 506, in dispatch
    response = handler(request, *args, **kwargs)
  File "/home/ubuntu/workspace/common/views.py", line 358, in post
    org_obj = serializer.save()
  File "/home/ubuntu/venv/lib/python3.8/site-packages/rest_framework/serializers.py", line 212, in save
    self.instance = self.create(validated_data)
  File "/home/ubuntu/venv/lib/python3.8/site-packages/rest_framework/serializers.py", line 962, in create
    instance = ModelClass._default_manager.create(**validated_data)
  File "/home/ubuntu/venv/lib/python3.8/site-packages/django/db/models/manager.py", line 85, in manager_method
    return getattr(self.get_queryset(), name)(*args, **kwargs)
  File "/home/ubuntu/venv/lib/python3.8/site-packages/django/db/models/query.py", line 671, in create
    obj.save(force_insert=True, using=self.db)
  File "/home/ubuntu/venv/lib/python3.8/site-packages/django/db/models/base.py", line 831, in save
    self.save_base(
  File "/home/ubuntu/venv/lib/python3.8/site-packages/django/db/models/base.py", line 882, in save_base
    updated = self._save_table(
  File "/home/ubuntu/venv/lib/python3.8/site-packages/django/db/models/base.py", line 1025, in _save_table
    results = self._do_insert(
  File "/home/ubuntu/venv/lib/python3.8/site-packages/django/db/models/base.py", line 1066, in _do_insert
    return manager._insert(
  File "/home/ubuntu/venv/lib/python3.8/site-packages/django/db/models/manager.py", line 85, in manager_method
    return getattr(self.get_queryset(), name)(*args, **kwargs)
  File "/home/ubuntu/venv/lib/python3.8/site-packages/django/db/models/query.py", line 1790, in _insert
    return query.get_compiler(using=using).execute_sql(returning_fields)
  File "/home/ubuntu/venv/lib/python3.8/site-packages/django/db/models/sql/compiler.py", line 1657, in execute_sql
    cursor.execute(sql, params)
  File "/home/ubuntu/venv/lib/python3.8/site-packages/django/db/backends/utils.py", line 103, in execute
    return super().execute(sql, params)
  File "/home/ubuntu/venv/lib/python3.8/site-packages/django/db/backends/utils.py", line 67, in execute
    return self._execute_with_wrappers(
  File "/home/ubuntu/venv/lib/python3.8/site-packages/django/db/backends/utils.py", line 80, in _execute_with_wrappers
    return executor(sql, params, many, context)
  File "/home/ubuntu/venv/lib/python3.8/site-packages/django/db/backends/utils.py", line 89, in _execute
    return self.cursor.execute(sql, params)
  File "/home/ubuntu/venv/lib/python3.8/site-packages/django/db/utils.py", line 91, in __exit__
    raise dj_exc_value.with_traceback(traceback) from exc_value
  File "/home/ubuntu/venv/lib/python3.8/site-packages/django/db/backends/utils.py", line 89, in _execute
    return self.cursor.execute(sql, params)
django.db.utils.DataError: value too long for type character varying(3)

Internal Server Error: /api/accounts/
Traceback (most recent call last):
  File "/home/ubuntu/venv/lib/python3.8/site-packages/django/core/handlers/exception.py", line 55, in inner
    response = get_response(request)
  File "/home/ubuntu/workspace/common/middleware/get_company.py", line 35, in __call__
    self.process_request(request)
  File "/home/ubuntu/workspace/common/middleware/get_company.py", line 47, in process_request
    org = Org.objects.get(id=org_id)
  File "/home/ubuntu/venv/lib/python3.8/site-packages/django/db/models/manager.py", line 85, in manager_method
    return getattr(self.get_queryset(), name)(*args, **kwargs)
  File "/home/ubuntu/venv/lib/python3.8/site-packages/django/db/models/query.py", line 650, in get
    raise self.model.DoesNotExist(
common.models.Org.DoesNotExist: Org matching query does not exist.
Internal Server Error: /api/accounts/
Traceback (most recent call last):
  File "/home/ubuntu/venv/lib/python3.8/site-packages/django/db/models/fields/__init__.py", line 2018, in get_prep_value
    return int(value)
ValueError: invalid literal for int() with base 10: 'null'

The above exception was the direct cause of the following exception:

Traceback (most recent call last):
  File "/home/ubuntu/venv/lib/python3.8/site-packages/django/core/handlers/exception.py", line 55, in inner
    response = get_response(request)
  File "/home/ubuntu/workspace/common/middleware/get_company.py", line 35, in __call__
    self.process_request(request)
  File "/home/ubuntu/workspace/common/middleware/get_company.py", line 47, in process_request
    org = Org.objects.get(id=org_id)
  File "/home/ubuntu/venv/lib/python3.8/site-packages/django/db/models/manager.py", line 85, in manager_method
    return getattr(self.get_queryset(), name)(*args, **kwargs)
  File "/home/ubuntu/venv/lib/python3.8/site-packages/django/db/models/query.py", line 636, in get
    clone = self._chain() if self.query.combinator else self.filter(*args, **kwargs)
  File "/home/ubuntu/venv/lib/python3.8/site-packages/django/db/models/query.py", line 1420, in filter
    return self._filter_or_exclude(False, args, kwargs)
  File "/home/ubuntu/venv/lib/python3.8/site-packages/django/db/models/query.py", line 1438, in _filter_or_exclude
    clone._filter_or_exclude_inplace(negate, args, kwargs)
  File "/home/ubuntu/venv/lib/python3.8/site-packages/django/db/models/query.py", line 1445, in _filter_or_exclude_inplace
    self._query.add_q(Q(*args, **kwargs))
  File "/home/ubuntu/venv/lib/python3.8/site-packages/django/db/models/sql/query.py", line 1532, in add_q
    clause, _ = self._add_q(q_object, self.used_aliases)
  File "/home/ubuntu/venv/lib/python3.8/site-packages/django/db/models/sql/query.py", line 1562, in _add_q
    child_clause, needed_inner = self.build_filter(
  File "/home/ubuntu/venv/lib/python3.8/site-packages/django/db/models/sql/query.py", line 1478, in build_filter
    condition = self.build_lookup(lookups, col, value)
  File "/home/ubuntu/venv/lib/python3.8/site-packages/django/db/models/sql/query.py", line 1303, in build_lookup
    lookup = lookup_class(lhs, rhs)
  File "/home/ubuntu/venv/lib/python3.8/site-packages/django/db/models/lookups.py", line 27, in __init__
    self.rhs = self.get_prep_lookup()
  File "/home/ubuntu/venv/lib/python3.8/site-packages/django/db/models/lookups.py", line 341, in get_prep_lookup
    return super().get_prep_lookup()
  File "/home/ubuntu/venv/lib/python3.8/site-packages/django/db/models/lookups.py", line 85, in get_prep_lookup
    return self.lhs.output_field.get_prep_value(self.rhs)
  File "/home/ubuntu/venv/lib/python3.8/site-packages/django/db/models/fields/__init__.py", line 2020, in get_prep_value
    raise e.__class__(
ValueError: Field 'id' expected a number but got 'null'.
Internal Server Error: /api/accounts/
Traceback (most recent call last):
  File "/home/ubuntu/venv/lib/python3.8/site-packages/django/db/models/fields/__init__.py", line 2018, in get_prep_value
    return int(value)
ValueError: invalid literal for int() with base 10: 'null'

The above exception was the direct cause of the following exception:

Traceback (most recent call last):
  File "/home/ubuntu/venv/lib/python3.8/site-packages/django/core/handlers/exception.py", line 55, in inner
    response = get_response(request)
  File "/home/ubuntu/workspace/common/middleware/get_company.py", line 35, in __call__
    self.process_request(request)
  File "/home/ubuntu/workspace/common/middleware/get_company.py", line 47, in process_request
    org = Org.objects.get(id=org_id)
  File "/home/ubuntu/venv/lib/python3.8/site-packages/django/db/models/manager.py", line 85, in manager_method
    return getattr(self.get_queryset(), name)(*args, **kwargs)
  File "/home/ubuntu/venv/lib/python3.8/site-packages/django/db/models/query.py", line 636, in get
    clone = self._chain() if self.query.combinator else self.filter(*args, **kwargs)
  File "/home/ubuntu/venv/lib/python3.8/site-packages/django/db/models/query.py", line 1420, in filter
    return self._filter_or_exclude(False, args, kwargs)
  File "/home/ubuntu/venv/lib/python3.8/site-packages/django/db/models/query.py", line 1438, in _filter_or_exclude
    clone._filter_or_exclude_inplace(negate, args, kwargs)
  File "/home/ubuntu/venv/lib/python3.8/site-packages/django/db/models/query.py", line 1445, in _filter_or_exclude_inplace
    self._query.add_q(Q(*args, **kwargs))
  File "/home/ubuntu/venv/lib/python3.8/site-packages/django/db/models/sql/query.py", line 1532, in add_q
    clause, _ = self._add_q(q_object, self.used_aliases)
  File "/home/ubuntu/venv/lib/python3.8/site-packages/django/db/models/sql/query.py", line 1562, in _add_q
    child_clause, needed_inner = self.build_filter(
  File "/home/ubuntu/venv/lib/python3.8/site-packages/django/db/models/sql/query.py", line 1478, in build_filter
    condition = self.build_lookup(lookups, col, value)
  File "/home/ubuntu/venv/lib/python3.8/site-packages/django/db/models/sql/query.py", line 1303, in build_lookup
    lookup = lookup_class(lhs, rhs)
  File "/home/ubuntu/venv/lib/python3.8/site-packages/django/db/models/lookups.py", line 27, in __init__
    self.rhs = self.get_prep_lookup()
  File "/home/ubuntu/venv/lib/python3.8/site-packages/django/db/models/lookups.py", line 341, in get_prep_lookup
    return super().get_prep_lookup()
  File "/home/ubuntu/venv/lib/python3.8/site-packages/django/db/models/lookups.py", line 85, in get_prep_lookup
    return self.lhs.output_field.get_prep_value(self.rhs)
  File "/home/ubuntu/venv/lib/python3.8/site-packages/django/db/models/fields/__init__.py", line 2020, in get_prep_value
    raise e.__class__(
ValueError: Field 'id' expected a number but got 'null'.
/home/ubuntu/workspace/accounts/views.py changed, reloading.
Watching for file changes with StatReloader
/home/ubuntu/workspace/accounts/views.py changed, reloading.
Watching for file changes with StatReloader
/home/ubuntu/workspace/accounts/views.py changed, reloading.
Watching for file changes with StatReloader
/home/ubuntu/workspace/accounts/views.py changed, reloading.
Watching for file changes with StatReloader
/home/ubuntu/workspace/accounts/views.py changed, reloading.
Watching for file changes with StatReloader
Internal Server Error: /api/accounts/
Traceback (most recent call last):
  File "/home/ubuntu/venv/lib/python3.8/site-packages/django/db/models/fields/__init__.py", line 2018, in get_prep_value
    return int(value)
ValueError: invalid literal for int() with base 10: 'null'

The above exception was the direct cause of the following exception:

Traceback (most recent call last):
  File "/home/ubuntu/venv/lib/python3.8/site-packages/django/core/handlers/exception.py", line 55, in inner
    response = get_response(request)
  File "/home/ubuntu/workspace/common/middleware/get_company.py", line 35, in __call__
    self.process_request(request)
  File "/home/ubuntu/workspace/common/middleware/get_company.py", line 47, in process_request
    org = Org.objects.get(id=org_id)
  File "/home/ubuntu/venv/lib/python3.8/site-packages/django/db/models/manager.py", line 85, in manager_method
    return getattr(self.get_queryset(), name)(*args, **kwargs)
  File "/home/ubuntu/venv/lib/python3.8/site-packages/django/db/models/query.py", line 636, in get
    clone = self._chain() if self.query.combinator else self.filter(*args, **kwargs)
  File "/home/ubuntu/venv/lib/python3.8/site-packages/django/db/models/query.py", line 1420, in filter
    return self._filter_or_exclude(False, args, kwargs)
  File "/home/ubuntu/venv/lib/python3.8/site-packages/django/db/models/query.py", line 1438, in _filter_or_exclude
    clone._filter_or_exclude_inplace(negate, args, kwargs)
  File "/home/ubuntu/venv/lib/python3.8/site-packages/django/db/models/query.py", line 1445, in _filter_or_exclude_inplace
    self._query.add_q(Q(*args, **kwargs))
  File "/home/ubuntu/venv/lib/python3.8/site-packages/django/db/models/sql/query.py", line 1532, in add_q
    clause, _ = self._add_q(q_object, self.used_aliases)
  File "/home/ubuntu/venv/lib/python3.8/site-packages/django/db/models/sql/query.py", line 1562, in _add_q
    child_clause, needed_inner = self.build_filter(
  File "/home/ubuntu/venv/lib/python3.8/site-packages/django/db/models/sql/query.py", line 1478, in build_filter
    condition = self.build_lookup(lookups, col, value)
  File "/home/ubuntu/venv/lib/python3.8/site-packages/django/db/models/sql/query.py", line 1303, in build_lookup
    lookup = lookup_class(lhs, rhs)
  File "/home/ubuntu/venv/lib/python3.8/site-packages/django/db/models/lookups.py", line 27, in __init__
    self.rhs = self.get_prep_lookup()
  File "/home/ubuntu/venv/lib/python3.8/site-packages/django/db/models/lookups.py", line 341, in get_prep_lookup
    return super().get_prep_lookup()
  File "/home/ubuntu/venv/lib/python3.8/site-packages/django/db/models/lookups.py", line 85, in get_prep_lookup
    return self.lhs.output_field.get_prep_value(self.rhs)
  File "/home/ubuntu/venv/lib/python3.8/site-packages/django/db/models/fields/__init__.py", line 2020, in get_prep_value
    raise e.__class__(
ValueError: Field 'id' expected a number but got 'null'.
/home/ubuntu/workspace/accounts/views.py changed, reloading.
Watching for file changes with StatReloader
/home/ubuntu/workspace/accounts/views.py changed, reloading.
Watching for file changes with StatReloader
Internal Server Error: /api/accounts/
Traceback (most recent call last):
  File "/home/ubuntu/venv/lib/python3.8/site-packages/django/db/models/fields/__init__.py", line 2018, in get_prep_value
    return int(value)
ValueError: invalid literal for int() with base 10: 'null'

The above exception was the direct cause of the following exception:

Traceback (most recent call last):
  File "/home/ubuntu/venv/lib/python3.8/site-packages/django/core/handlers/exception.py", line 55, in inner
    response = get_response(request)
  File "/home/ubuntu/workspace/common/middleware/get_company.py", line 35, in __call__
    self.process_request(request)
  File "/home/ubuntu/workspace/common/middleware/get_company.py", line 47, in process_request
    org = Org.objects.get(id=org_id)
  File "/home/ubuntu/venv/lib/python3.8/site-packages/django/db/models/manager.py", line 85, in manager_method
    return getattr(self.get_queryset(), name)(*args, **kwargs)
  File "/home/ubuntu/venv/lib/python3.8/site-packages/django/db/models/query.py", line 636, in get
    clone = self._chain() if self.query.combinator else self.filter(*args, **kwargs)
  File "/home/ubuntu/venv/lib/python3.8/site-packages/django/db/models/query.py", line 1420, in filter
    return self._filter_or_exclude(False, args, kwargs)
  File "/home/ubuntu/venv/lib/python3.8/site-packages/django/db/models/query.py", line 1438, in _filter_or_exclude
    clone._filter_or_exclude_inplace(negate, args, kwargs)
  File "/home/ubuntu/venv/lib/python3.8/site-packages/django/db/models/query.py", line 1445, in _filter_or_exclude_inplace
    self._query.add_q(Q(*args, **kwargs))
  File "/home/ubuntu/venv/lib/python3.8/site-packages/django/db/models/sql/query.py", line 1532, in add_q
    clause, _ = self._add_q(q_object, self.used_aliases)
  File "/home/ubuntu/venv/lib/python3.8/site-packages/django/db/models/sql/query.py", line 1562, in _add_q
    child_clause, needed_inner = self.build_filter(
  File "/home/ubuntu/venv/lib/python3.8/site-packages/django/db/models/sql/query.py", line 1478, in build_filter
    condition = self.build_lookup(lookups, col, value)
  File "/home/ubuntu/venv/lib/python3.8/site-packages/django/db/models/sql/query.py", line 1303, in build_lookup
    lookup = lookup_class(lhs, rhs)
  File "/home/ubuntu/venv/lib/python3.8/site-packages/django/db/models/lookups.py", line 27, in __init__
    self.rhs = self.get_prep_lookup()
  File "/home/ubuntu/venv/lib/python3.8/site-packages/django/db/models/lookups.py", line 341, in get_prep_lookup
    return super().get_prep_lookup()
  File "/home/ubuntu/venv/lib/python3.8/site-packages/django/db/models/lookups.py", line 85, in get_prep_lookup
    return self.lhs.output_field.get_prep_value(self.rhs)
  File "/home/ubuntu/venv/lib/python3.8/site-packages/django/db/models/fields/__init__.py", line 2020, in get_prep_value
    raise e.__class__(
ValueError: Field 'id' expected a number but got 'null'.
Internal Server Error: /api/accounts/
Traceback (most recent call last):
  File "/home/ubuntu/venv/lib/python3.8/site-packages/django/db/models/fields/__init__.py", line 2018, in get_prep_value
    return int(value)
ValueError: invalid literal for int() with base 10: 'null'

The above exception was the direct cause of the following exception:

Traceback (most recent call last):
  File "/home/ubuntu/venv/lib/python3.8/site-packages/django/core/handlers/exception.py", line 55, in inner
    response = get_response(request)
  File "/home/ubuntu/workspace/common/middleware/get_company.py", line 35, in __call__
    self.process_request(request)
  File "/home/ubuntu/workspace/common/middleware/get_company.py", line 47, in process_request
    org = Org.objects.get(id=org_id)
  File "/home/ubuntu/venv/lib/python3.8/site-packages/django/db/models/manager.py", line 85, in manager_method
    return getattr(self.get_queryset(), name)(*args, **kwargs)
  File "/home/ubuntu/venv/lib/python3.8/site-packages/django/db/models/query.py", line 636, in get
    clone = self._chain() if self.query.combinator else self.filter(*args, **kwargs)
  File "/home/ubuntu/venv/lib/python3.8/site-packages/django/db/models/query.py", line 1420, in filter
    return self._filter_or_exclude(False, args, kwargs)
  File "/home/ubuntu/venv/lib/python3.8/site-packages/django/db/models/query.py", line 1438, in _filter_or_exclude
    clone._filter_or_exclude_inplace(negate, args, kwargs)
  File "/home/ubuntu/venv/lib/python3.8/site-packages/django/db/models/query.py", line 1445, in _filter_or_exclude_inplace
    self._query.add_q(Q(*args, **kwargs))
  File "/home/ubuntu/venv/lib/python3.8/site-packages/django/db/models/sql/query.py", line 1532, in add_q
    clause, _ = self._add_q(q_object, self.used_aliases)
  File "/home/ubuntu/venv/lib/python3.8/site-packages/django/db/models/sql/query.py", line 1562, in _add_q
    child_clause, needed_inner = self.build_filter(
  File "/home/ubuntu/venv/lib/python3.8/site-packages/django/db/models/sql/query.py", line 1478, in build_filter
    condition = self.build_lookup(lookups, col, value)
  File "/home/ubuntu/venv/lib/python3.8/site-packages/django/db/models/sql/query.py", line 1303, in build_lookup
    lookup = lookup_class(lhs, rhs)
  File "/home/ubuntu/venv/lib/python3.8/site-packages/django/db/models/lookups.py", line 27, in __init__
    self.rhs = self.get_prep_lookup()
  File "/home/ubuntu/venv/lib/python3.8/site-packages/django/db/models/lookups.py", line 341, in get_prep_lookup
    return super().get_prep_lookup()
  File "/home/ubuntu/venv/lib/python3.8/site-packages/django/db/models/lookups.py", line 85, in get_prep_lookup
    return self.lhs.output_field.get_prep_value(self.rhs)
  File "/home/ubuntu/venv/lib/python3.8/site-packages/django/db/models/fields/__init__.py", line 2020, in get_prep_value
    raise e.__class__(
ValueError: Field 'id' expected a number but got 'null'.
/home/ubuntu/workspace/common/middleware/get_company.py changed, reloading.
Watching for file changes with StatReloader
/home/ubuntu/workspace/common/middleware/get_company.py changed, reloading.
Watching for file changes with StatReloader
Internal Server Error: /api/accounts/
Traceback (most recent call last):
  File "/home/ubuntu/venv/lib/python3.8/site-packages/django/db/models/fields/__init__.py", line 2018, in get_prep_value
    return int(value)
ValueError: invalid literal for int() with base 10: 'null'

The above exception was the direct cause of the following exception:

Traceback (most recent call last):
  File "/home/ubuntu/venv/lib/python3.8/site-packages/django/core/handlers/exception.py", line 55, in inner
    response = get_response(request)
  File "/home/ubuntu/workspace/common/middleware/get_company.py", line 35, in __call__
    self.process_request(request)
  File "/home/ubuntu/workspace/common/middleware/get_company.py", line 48, in process_request
    org = Org.objects.get(id=org_id)
  File "/home/ubuntu/venv/lib/python3.8/site-packages/django/db/models/manager.py", line 85, in manager_method
    return getattr(self.get_queryset(), name)(*args, **kwargs)
  File "/home/ubuntu/venv/lib/python3.8/site-packages/django/db/models/query.py", line 636, in get
    clone = self._chain() if self.query.combinator else self.filter(*args, **kwargs)
  File "/home/ubuntu/venv/lib/python3.8/site-packages/django/db/models/query.py", line 1420, in filter
    return self._filter_or_exclude(False, args, kwargs)
  File "/home/ubuntu/venv/lib/python3.8/site-packages/django/db/models/query.py", line 1438, in _filter_or_exclude
    clone._filter_or_exclude_inplace(negate, args, kwargs)
  File "/home/ubuntu/venv/lib/python3.8/site-packages/django/db/models/query.py", line 1445, in _filter_or_exclude_inplace
    self._query.add_q(Q(*args, **kwargs))
  File "/home/ubuntu/venv/lib/python3.8/site-packages/django/db/models/sql/query.py", line 1532, in add_q
    clause, _ = self._add_q(q_object, self.used_aliases)
  File "/home/ubuntu/venv/lib/python3.8/site-packages/django/db/models/sql/query.py", line 1562, in _add_q
    child_clause, needed_inner = self.build_filter(
  File "/home/ubuntu/venv/lib/python3.8/site-packages/django/db/models/sql/query.py", line 1478, in build_filter
    condition = self.build_lookup(lookups, col, value)
  File "/home/ubuntu/venv/lib/python3.8/site-packages/django/db/models/sql/query.py", line 1303, in build_lookup
    lookup = lookup_class(lhs, rhs)
  File "/home/ubuntu/venv/lib/python3.8/site-packages/django/db/models/lookups.py", line 27, in __init__
    self.rhs = self.get_prep_lookup()
  File "/home/ubuntu/venv/lib/python3.8/site-packages/django/db/models/lookups.py", line 341, in get_prep_lookup
    return super().get_prep_lookup()
  File "/home/ubuntu/venv/lib/python3.8/site-packages/django/db/models/lookups.py", line 85, in get_prep_lookup
    return self.lhs.output_field.get_prep_value(self.rhs)
  File "/home/ubuntu/venv/lib/python3.8/site-packages/django/db/models/fields/__init__.py", line 2020, in get_prep_value
    raise e.__class__(
ValueError: Field 'id' expected a number but got 'null'.
Internal Server Error: /api/accounts/
Traceback (most recent call last):
  File "/home/ubuntu/venv/lib/python3.8/site-packages/django/core/handlers/exception.py", line 55, in inner
    response = get_response(request)
  File "/home/ubuntu/workspace/common/middleware/get_company.py", line 35, in __call__
    self.process_request(request)
  File "/home/ubuntu/workspace/common/middleware/get_company.py", line 48, in process_request
    org = Org.objects.get(id=org_id)
  File "/home/ubuntu/venv/lib/python3.8/site-packages/django/db/models/manager.py", line 85, in manager_method
    return getattr(self.get_queryset(), name)(*args, **kwargs)
  File "/home/ubuntu/venv/lib/python3.8/site-packages/django/db/models/query.py", line 650, in get
    raise self.model.DoesNotExist(
common.models.Org.DoesNotExist: Org matching query does not exist.
Internal Server Error: /api/auth/create-org/
Traceback (most recent call last):
  File "/home/ubuntu/venv/lib/python3.8/site-packages/django/db/backends/utils.py", line 89, in _execute
    return self.cursor.execute(sql, params)
psycopg2.errors.StringDataRightTruncation: value too long for type character varying(3)


The above exception was the direct cause of the following exception:

Traceback (most recent call last):
  File "/home/ubuntu/venv/lib/python3.8/site-packages/django/core/handlers/exception.py", line 55, in inner
    response = get_response(request)
  File "/home/ubuntu/venv/lib/python3.8/site-packages/django/core/handlers/base.py", line 197, in _get_response
    response = wrapped_callback(request, *callback_args, **callback_kwargs)
  File "/home/ubuntu/venv/lib/python3.8/site-packages/django/views/decorators/csrf.py", line 54, in wrapped_view
    return view_func(*args, **kwargs)
  File "/home/ubuntu/venv/lib/python3.8/site-packages/django/views/generic/base.py", line 103, in view
    return self.dispatch(request, *args, **kwargs)
  File "/home/ubuntu/venv/lib/python3.8/site-packages/rest_framework/views.py", line 509, in dispatch
    response = self.handle_exception(exc)
  File "/home/ubuntu/venv/lib/python3.8/site-packages/rest_framework/views.py", line 469, in handle_exception
    self.raise_uncaught_exception(exc)
  File "/home/ubuntu/venv/lib/python3.8/site-packages/rest_framework/views.py", line 480, in raise_uncaught_exception
    raise exc
  File "/home/ubuntu/venv/lib/python3.8/site-packages/rest_framework/views.py", line 506, in dispatch
    response = handler(request, *args, **kwargs)
  File "/home/ubuntu/workspace/common/views.py", line 358, in post
    org_obj = serializer.save()
  File "/home/ubuntu/venv/lib/python3.8/site-packages/rest_framework/serializers.py", line 212, in save
    self.instance = self.create(validated_data)
  File "/home/ubuntu/venv/lib/python3.8/site-packages/rest_framework/serializers.py", line 962, in create
    instance = ModelClass._default_manager.create(**validated_data)
  File "/home/ubuntu/venv/lib/python3.8/site-packages/django/db/models/manager.py", line 85, in manager_method
    return getattr(self.get_queryset(), name)(*args, **kwargs)
  File "/home/ubuntu/venv/lib/python3.8/site-packages/django/db/models/query.py", line 671, in create
    obj.save(force_insert=True, using=self.db)
  File "/home/ubuntu/venv/lib/python3.8/site-packages/django/db/models/base.py", line 831, in save
    self.save_base(
  File "/home/ubuntu/venv/lib/python3.8/site-packages/django/db/models/base.py", line 882, in save_base
    updated = self._save_table(
  File "/home/ubuntu/venv/lib/python3.8/site-packages/django/db/models/base.py", line 1025, in _save_table
    results = self._do_insert(
  File "/home/ubuntu/venv/lib/python3.8/site-packages/django/db/models/base.py", line 1066, in _do_insert
    return manager._insert(
  File "/home/ubuntu/venv/lib/python3.8/site-packages/django/db/models/manager.py", line 85, in manager_method
    return getattr(self.get_queryset(), name)(*args, **kwargs)
  File "/home/ubuntu/venv/lib/python3.8/site-packages/django/db/models/query.py", line 1790, in _insert
    return query.get_compiler(using=using).execute_sql(returning_fields)
  File "/home/ubuntu/venv/lib/python3.8/site-packages/django/db/models/sql/compiler.py", line 1657, in execute_sql
    cursor.execute(sql, params)
  File "/home/ubuntu/venv/lib/python3.8/site-packages/django/db/backends/utils.py", line 103, in execute
    return super().execute(sql, params)
  File "/home/ubuntu/venv/lib/python3.8/site-packages/django/db/backends/utils.py", line 67, in execute
    return self._execute_with_wrappers(
  File "/home/ubuntu/venv/lib/python3.8/site-packages/django/db/backends/utils.py", line 80, in _execute_with_wrappers
    return executor(sql, params, many, context)
  File "/home/ubuntu/venv/lib/python3.8/site-packages/django/db/backends/utils.py", line 89, in _execute
    return self.cursor.execute(sql, params)
  File "/home/ubuntu/venv/lib/python3.8/site-packages/django/db/utils.py", line 91, in __exit__
    raise dj_exc_value.with_traceback(traceback) from exc_value
  File "/home/ubuntu/venv/lib/python3.8/site-packages/django/db/backends/utils.py", line 89, in _execute
    return self.cursor.execute(sql, params)
django.db.utils.DataError: value too long for type character varying(3)

Internal Server Error: /api/auth/create-org/
Traceback (most recent call last):
  File "/home/ubuntu/venv/lib/python3.8/site-packages/django/db/backends/utils.py", line 89, in _execute
    return self.cursor.execute(sql, params)
psycopg2.errors.StringDataRightTruncation: value too long for type character varying(3)


The above exception was the direct cause of the following exception:

Traceback (most recent call last):
  File "/home/ubuntu/venv/lib/python3.8/site-packages/django/core/handlers/exception.py", line 55, in inner
    response = get_response(request)
  File "/home/ubuntu/venv/lib/python3.8/site-packages/django/core/handlers/base.py", line 197, in _get_response
    response = wrapped_callback(request, *callback_args, **callback_kwargs)
  File "/home/ubuntu/venv/lib/python3.8/site-packages/django/views/decorators/csrf.py", line 54, in wrapped_view
    return view_func(*args, **kwargs)
  File "/home/ubuntu/venv/lib/python3.8/site-packages/django/views/generic/base.py", line 103, in view
    return self.dispatch(request, *args, **kwargs)
  File "/home/ubuntu/venv/lib/python3.8/site-packages/rest_framework/views.py", line 509, in dispatch
    response = self.handle_exception(exc)
  File "/home/ubuntu/venv/lib/python3.8/site-packages/rest_framework/views.py", line 469, in handle_exception
    self.raise_uncaught_exception(exc)
  File "/home/ubuntu/venv/lib/python3.8/site-packages/rest_framework/views.py", line 480, in raise_uncaught_exception
    raise exc
  File "/home/ubuntu/venv/lib/python3.8/site-packages/rest_framework/views.py", line 506, in dispatch
    response = handler(request, *args, **kwargs)
  File "/home/ubuntu/workspace/common/views.py", line 358, in post
    org_obj = serializer.save()
  File "/home/ubuntu/venv/lib/python3.8/site-packages/rest_framework/serializers.py", line 212, in save
    self.instance = self.create(validated_data)
  File "/home/ubuntu/venv/lib/python3.8/site-packages/rest_framework/serializers.py", line 962, in create
    instance = ModelClass._default_manager.create(**validated_data)
  File "/home/ubuntu/venv/lib/python3.8/site-packages/django/db/models/manager.py", line 85, in manager_method
    return getattr(self.get_queryset(), name)(*args, **kwargs)
  File "/home/ubuntu/venv/lib/python3.8/site-packages/django/db/models/query.py", line 671, in create
    obj.save(force_insert=True, using=self.db)
  File "/home/ubuntu/venv/lib/python3.8/site-packages/django/db/models/base.py", line 831, in save
    self.save_base(
  File "/home/ubuntu/venv/lib/python3.8/site-packages/django/db/models/base.py", line 882, in save_base
    updated = self._save_table(
  File "/home/ubuntu/venv/lib/python3.8/site-packages/django/db/models/base.py", line 1025, in _save_table
    results = self._do_insert(
  File "/home/ubuntu/venv/lib/python3.8/site-packages/django/db/models/base.py", line 1066, in _do_insert
    return manager._insert(
  File "/home/ubuntu/venv/lib/python3.8/site-packages/django/db/models/manager.py", line 85, in manager_method
    return getattr(self.get_queryset(), name)(*args, **kwargs)
  File "/home/ubuntu/venv/lib/python3.8/site-packages/django/db/models/query.py", line 1790, in _insert
    return query.get_compiler(using=using).execute_sql(returning_fields)
  File "/home/ubuntu/venv/lib/python3.8/site-packages/django/db/models/sql/compiler.py", line 1657, in execute_sql
    cursor.execute(sql, params)
  File "/home/ubuntu/venv/lib/python3.8/site-packages/django/db/backends/utils.py", line 103, in execute
    return super().execute(sql, params)
  File "/home/ubuntu/venv/lib/python3.8/site-packages/django/db/backends/utils.py", line 67, in execute
    return self._execute_with_wrappers(
  File "/home/ubuntu/venv/lib/python3.8/site-packages/django/db/backends/utils.py", line 80, in _execute_with_wrappers
    return executor(sql, params, many, context)
  File "/home/ubuntu/venv/lib/python3.8/site-packages/django/db/backends/utils.py", line 89, in _execute
    return self.cursor.execute(sql, params)
  File "/home/ubuntu/venv/lib/python3.8/site-packages/django/db/utils.py", line 91, in __exit__
    raise dj_exc_value.with_traceback(traceback) from exc_value
  File "/home/ubuntu/venv/lib/python3.8/site-packages/django/db/backends/utils.py", line 89, in _execute
    return self.cursor.execute(sql, params)
django.db.utils.DataError: value too long for type character varying(3)

Bad Request: /api/leads/
Internal Server Error: /api/leads/
Traceback (most recent call last):
  File "/home/ubuntu/venv/lib/python3.8/site-packages/kombu/utils/functional.py", line 30, in __call__
    return self.__value__
AttributeError: 'ChannelPromise' object has no attribute '__value__'

During handling of the above exception, another exception occurred:

Traceback (most recent call last):
  File "/home/ubuntu/venv/lib/python3.8/site-packages/kombu/connection.py", line 446, in _reraise_as_library_errors
    yield
  File "/home/ubuntu/venv/lib/python3.8/site-packages/kombu/connection.py", line 433, in _ensure_connection
    return retry_over_time(
  File "/home/ubuntu/venv/lib/python3.8/site-packages/kombu/utils/functional.py", line 312, in retry_over_time
    return fun(*args, **kwargs)
  File "/home/ubuntu/venv/lib/python3.8/site-packages/kombu/connection.py", line 877, in _connection_factory
    self._connection = self._establish_connection()
  File "/home/ubuntu/venv/lib/python3.8/site-packages/kombu/connection.py", line 812, in _establish_connection
    conn = self.transport.establish_connection()
  File "/home/ubuntu/venv/lib/python3.8/site-packages/kombu/transport/pyamqp.py", line 201, in establish_connection
    conn.connect()
  File "/home/ubuntu/venv/lib/python3.8/site-packages/amqp/connection.py", line 323, in connect
    self.transport.connect()
  File "/home/ubuntu/venv/lib/python3.8/site-packages/amqp/transport.py", line 129, in connect
    self._connect(self.host, self.port, self.connect_timeout)
  File "/home/ubuntu/venv/lib/python3.8/site-packages/amqp/transport.py", line 184, in _connect
    self.sock.connect(sa)
ConnectionRefusedError: [Errno 111] Connection refused

The above exception was the direct cause of the following exception:

Traceback (most recent call last):
  File "/home/ubuntu/venv/lib/python3.8/site-packages/django/core/handlers/exception.py", line 55, in inner
    response = get_response(request)
  File "/home/ubuntu/venv/lib/python3.8/site-packages/django/core/handlers/base.py", line 197, in _get_response
    response = wrapped_callback(request, *callback_args, **callback_kwargs)
  File "/home/ubuntu/venv/lib/python3.8/site-packages/django/views/decorators/csrf.py", line 54, in wrapped_view
    return view_func(*args, **kwargs)
  File "/home/ubuntu/venv/lib/python3.8/site-packages/django/views/generic/base.py", line 103, in view
    return self.dispatch(request, *args, **kwargs)
  File "/home/ubuntu/venv/lib/python3.8/site-packages/rest_framework/views.py", line 509, in dispatch
    response = self.handle_exception(exc)
  File "/home/ubuntu/venv/lib/python3.8/site-packages/rest_framework/views.py", line 469, in handle_exception
    self.raise_uncaught_exception(exc)
  File "/home/ubuntu/venv/lib/python3.8/site-packages/rest_framework/views.py", line 480, in raise_uncaught_exception
    raise exc
  File "/home/ubuntu/venv/lib/python3.8/site-packages/rest_framework/views.py", line 506, in dispatch
    response = handler(request, *args, **kwargs)
  File "/home/ubuntu/workspace/leads/views.py", line 182, in post
    send_email_to_assigned_user.delay(
  File "/home/ubuntu/venv/lib/python3.8/site-packages/celery/app/task.py", line 425, in delay
    return self.apply_async(args, kwargs)
  File "/home/ubuntu/venv/lib/python3.8/site-packages/celery/app/task.py", line 575, in apply_async
    return app.send_task(
  File "/home/ubuntu/venv/lib/python3.8/site-packages/celery/app/base.py", line 788, in send_task
    amqp.send_task_message(P, name, message, **options)
  File "/home/ubuntu/venv/lib/python3.8/site-packages/celery/app/amqp.py", line 510, in send_task_message
    ret = producer.publish(
  File "/home/ubuntu/venv/lib/python3.8/site-packages/kombu/messaging.py", line 177, in publish
    return _publish(
  File "/home/ubuntu/venv/lib/python3.8/site-packages/kombu/connection.py", line 523, in _ensured
    return fun(*args, **kwargs)
  File "/home/ubuntu/venv/lib/python3.8/site-packages/kombu/messaging.py", line 186, in _publish
    channel = self.channel
  File "/home/ubuntu/venv/lib/python3.8/site-packages/kombu/messaging.py", line 209, in _get_channel
    channel = self._channel = channel()
  File "/home/ubuntu/venv/lib/python3.8/site-packages/kombu/utils/functional.py", line 32, in __call__
    value = self.__value__ = self.__contract__()
  File "/home/ubuntu/venv/lib/python3.8/site-packages/kombu/messaging.py", line 225, in <lambda>
    channel = ChannelPromise(lambda: connection.default_channel)
  File "/home/ubuntu/venv/lib/python3.8/site-packages/kombu/connection.py", line 895, in default_channel
    self._ensure_connection(**conn_opts)
  File "/home/ubuntu/venv/lib/python3.8/site-packages/kombu/connection.py", line 433, in _ensure_connection
    return retry_over_time(
  File "/usr/lib/python3.8/contextlib.py", line 131, in __exit__
    self.gen.throw(type, value, traceback)
  File "/home/ubuntu/venv/lib/python3.8/site-packages/kombu/connection.py", line 450, in _reraise_as_library_errors
    raise ConnectionError(str(exc)) from exc
kombu.exceptions.OperationalError: [Errno 111] Connection refused
Bad Request: /api/leads/
Bad Request: /api/contacts/
Internal Server Error: /api/contacts/
Traceback (most recent call last):
  File "/home/ubuntu/venv/lib/python3.8/site-packages/kombu/utils/functional.py", line 30, in __call__
    return self.__value__
AttributeError: 'ChannelPromise' object has no attribute '__value__'

During handling of the above exception, another exception occurred:

Traceback (most recent call last):
  File "/home/ubuntu/venv/lib/python3.8/site-packages/kombu/connection.py", line 446, in _reraise_as_library_errors
    yield
  File "/home/ubuntu/venv/lib/python3.8/site-packages/kombu/connection.py", line 433, in _ensure_connection
    return retry_over_time(
  File "/home/ubuntu/venv/lib/python3.8/site-packages/kombu/utils/functional.py", line 312, in retry_over_time
    return fun(*args, **kwargs)
  File "/home/ubuntu/venv/lib/python3.8/site-packages/kombu/connection.py", line 877, in _connection_factory
    self._connection = self._establish_connection()
  File "/home/ubuntu/venv/lib/python3.8/site-packages/kombu/connection.py", line 812, in _establish_connection
    conn = self.transport.establish_connection()
  File "/home/ubuntu/venv/lib/python3.8/site-packages/kombu/transport/pyamqp.py", line 201, in establish_connection
    conn.connect()
  File "/home/ubuntu/venv/lib/python3.8/site-packages/amqp/connection.py", line 323, in connect
    self.transport.connect()
  File "/home/ubuntu/venv/lib/python3.8/site-packages/amqp/transport.py", line 129, in connect
    self._connect(self.host, self.port, self.connect_timeout)
  File "/home/ubuntu/venv/lib/python3.8/site-packages/amqp/transport.py", line 184, in _connect
    self.sock.connect(sa)
ConnectionRefusedError: [Errno 111] Connection refused

The above exception was the direct cause of the following exception:

Traceback (most recent call last):
  File "/home/ubuntu/venv/lib/python3.8/site-packages/django/core/handlers/exception.py", line 55, in inner
    response = get_response(request)
  File "/home/ubuntu/venv/lib/python3.8/site-packages/django/core/handlers/base.py", line 197, in _get_response
    response = wrapped_callback(request, *callback_args, **callback_kwargs)
  File "/home/ubuntu/venv/lib/python3.8/site-packages/django/views/decorators/csrf.py", line 54, in wrapped_view
    return view_func(*args, **kwargs)
  File "/home/ubuntu/venv/lib/python3.8/site-packages/django/views/generic/base.py", line 103, in view
    return self.dispatch(request, *args, **kwargs)
  File "/home/ubuntu/venv/lib/python3.8/site-packages/rest_framework/views.py", line 509, in dispatch
    response = self.handle_exception(exc)
  File "/home/ubuntu/venv/lib/python3.8/site-packages/rest_framework/views.py", line 469, in handle_exception
    self.raise_uncaught_exception(exc)
  File "/home/ubuntu/venv/lib/python3.8/site-packages/rest_framework/views.py", line 480, in raise_uncaught_exception
    raise exc
  File "/home/ubuntu/venv/lib/python3.8/site-packages/rest_framework/views.py", line 506, in dispatch
    response = handler(request, *args, **kwargs)
  File "/home/ubuntu/workspace/contacts/views.py", line 127, in post
    send_email_to_assigned_user.delay(
  File "/home/ubuntu/venv/lib/python3.8/site-packages/celery/app/task.py", line 425, in delay
    return self.apply_async(args, kwargs)
  File "/home/ubuntu/venv/lib/python3.8/site-packages/celery/app/task.py", line 575, in apply_async
    return app.send_task(
  File "/home/ubuntu/venv/lib/python3.8/site-packages/celery/app/base.py", line 788, in send_task
    amqp.send_task_message(P, name, message, **options)
  File "/home/ubuntu/venv/lib/python3.8/site-packages/celery/app/amqp.py", line 510, in send_task_message
    ret = producer.publish(
  File "/home/ubuntu/venv/lib/python3.8/site-packages/kombu/messaging.py", line 177, in publish
    return _publish(
  File "/home/ubuntu/venv/lib/python3.8/site-packages/kombu/connection.py", line 523, in _ensured
    return fun(*args, **kwargs)
  File "/home/ubuntu/venv/lib/python3.8/site-packages/kombu/messaging.py", line 186, in _publish
    channel = self.channel
  File "/home/ubuntu/venv/lib/python3.8/site-packages/kombu/messaging.py", line 209, in _get_channel
    channel = self._channel = channel()
  File "/home/ubuntu/venv/lib/python3.8/site-packages/kombu/utils/functional.py", line 32, in __call__
    value = self.__value__ = self.__contract__()
  File "/home/ubuntu/venv/lib/python3.8/site-packages/kombu/messaging.py", line 225, in <lambda>
    channel = ChannelPromise(lambda: connection.default_channel)
  File "/home/ubuntu/venv/lib/python3.8/site-packages/kombu/connection.py", line 895, in default_channel
    self._ensure_connection(**conn_opts)
  File "/home/ubuntu/venv/lib/python3.8/site-packages/kombu/connection.py", line 433, in _ensure_connection
    return retry_over_time(
  File "/usr/lib/python3.8/contextlib.py", line 131, in __exit__
    self.gen.throw(type, value, traceback)
  File "/home/ubuntu/venv/lib/python3.8/site-packages/kombu/connection.py", line 450, in _reraise_as_library_errors
    raise ConnectionError(str(exc)) from exc
kombu.exceptions.OperationalError: [Errno 111] Connection refused
Bad Request: /api/contacts/
Internal Server Error: /api/contacts/
Traceback (most recent call last):
  File "/home/ubuntu/venv/lib/python3.8/site-packages/kombu/utils/functional.py", line 30, in __call__
    return self.__value__
AttributeError: 'ChannelPromise' object has no attribute '__value__'

During handling of the above exception, another exception occurred:

Traceback (most recent call last):
  File "/home/ubuntu/venv/lib/python3.8/site-packages/kombu/connection.py", line 446, in _reraise_as_library_errors
    yield
  File "/home/ubuntu/venv/lib/python3.8/site-packages/kombu/connection.py", line 433, in _ensure_connection
    return retry_over_time(
  File "/home/ubuntu/venv/lib/python3.8/site-packages/kombu/utils/functional.py", line 312, in retry_over_time
    return fun(*args, **kwargs)
  File "/home/ubuntu/venv/lib/python3.8/site-packages/kombu/connection.py", line 877, in _connection_factory
    self._connection = self._establish_connection()
  File "/home/ubuntu/venv/lib/python3.8/site-packages/kombu/connection.py", line 812, in _establish_connection
    conn = self.transport.establish_connection()
  File "/home/ubuntu/venv/lib/python3.8/site-packages/kombu/transport/pyamqp.py", line 201, in establish_connection
    conn.connect()
  File "/home/ubuntu/venv/lib/python3.8/site-packages/amqp/connection.py", line 323, in connect
    self.transport.connect()
  File "/home/ubuntu/venv/lib/python3.8/site-packages/amqp/transport.py", line 129, in connect
    self._connect(self.host, self.port, self.connect_timeout)
  File "/home/ubuntu/venv/lib/python3.8/site-packages/amqp/transport.py", line 184, in _connect
    self.sock.connect(sa)
ConnectionRefusedError: [Errno 111] Connection refused

The above exception was the direct cause of the following exception:

Traceback (most recent call last):
  File "/home/ubuntu/venv/lib/python3.8/site-packages/django/core/handlers/exception.py", line 55, in inner
    response = get_response(request)
  File "/home/ubuntu/venv/lib/python3.8/site-packages/django/core/handlers/base.py", line 197, in _get_response
    response = wrapped_callback(request, *callback_args, **callback_kwargs)
  File "/home/ubuntu/venv/lib/python3.8/site-packages/django/views/decorators/csrf.py", line 54, in wrapped_view
    return view_func(*args, **kwargs)
  File "/home/ubuntu/venv/lib/python3.8/site-packages/django/views/generic/base.py", line 103, in view
    return self.dispatch(request, *args, **kwargs)
  File "/home/ubuntu/venv/lib/python3.8/site-packages/rest_framework/views.py", line 509, in dispatch
    response = self.handle_exception(exc)
  File "/home/ubuntu/venv/lib/python3.8/site-packages/rest_framework/views.py", line 469, in handle_exception
    self.raise_uncaught_exception(exc)
  File "/home/ubuntu/venv/lib/python3.8/site-packages/rest_framework/views.py", line 480, in raise_uncaught_exception
    raise exc
  File "/home/ubuntu/venv/lib/python3.8/site-packages/rest_framework/views.py", line 506, in dispatch
    response = handler(request, *args, **kwargs)
  File "/home/ubuntu/workspace/contacts/views.py", line 127, in post
    send_email_to_assigned_user.delay(
  File "/home/ubuntu/venv/lib/python3.8/site-packages/celery/app/task.py", line 425, in delay
    return self.apply_async(args, kwargs)
  File "/home/ubuntu/venv/lib/python3.8/site-packages/celery/app/task.py", line 575, in apply_async
    return app.send_task(
  File "/home/ubuntu/venv/lib/python3.8/site-packages/celery/app/base.py", line 788, in send_task
    amqp.send_task_message(P, name, message, **options)
  File "/home/ubuntu/venv/lib/python3.8/site-packages/celery/app/amqp.py", line 510, in send_task_message
    ret = producer.publish(
  File "/home/ubuntu/venv/lib/python3.8/site-packages/kombu/messaging.py", line 177, in publish
    return _publish(
  File "/home/ubuntu/venv/lib/python3.8/site-packages/kombu/connection.py", line 523, in _ensured
    return fun(*args, **kwargs)
  File "/home/ubuntu/venv/lib/python3.8/site-packages/kombu/messaging.py", line 186, in _publish
    channel = self.channel
  File "/home/ubuntu/venv/lib/python3.8/site-packages/kombu/messaging.py", line 209, in _get_channel
    channel = self._channel = channel()
  File "/home/ubuntu/venv/lib/python3.8/site-packages/kombu/utils/functional.py", line 32, in __call__
    value = self.__value__ = self.__contract__()
  File "/home/ubuntu/venv/lib/python3.8/site-packages/kombu/messaging.py", line 225, in <lambda>
    channel = ChannelPromise(lambda: connection.default_channel)
  File "/home/ubuntu/venv/lib/python3.8/site-packages/kombu/connection.py", line 895, in default_channel
    self._ensure_connection(**conn_opts)
  File "/home/ubuntu/venv/lib/python3.8/site-packages/kombu/connection.py", line 433, in _ensure_connection
    return retry_over_time(
  File "/usr/lib/python3.8/contextlib.py", line 131, in __exit__
    self.gen.throw(type, value, traceback)
  File "/home/ubuntu/venv/lib/python3.8/site-packages/kombu/connection.py", line 450, in _reraise_as_library_errors
    raise ConnectionError(str(exc)) from exc
kombu.exceptions.OperationalError: [Errno 111] Connection refused
Not Found: /api/auth/companies-list/
Not Found: /api/auth/companies-list/
Bad Request: /api/auth/login/
Bad Request: /api/auth/login/
Bad Request: /api/auth/login/
Bad Request: /api/auth/login/
Bad Request: /api/auth/login/
Bad Request: /api/auth/login/
Bad Request: /api/auth/login/
Bad Request: /api/auth/login/
Bad Request: /api/auth/login/
Bad Request: /api/auth/login/
Bad Request: /api/auth/login/
Bad Request: /api/leads/
Bad Request: /api/leads/
Bad Request: /api/leads/
Bad Request: /api/leads/
Bad Request: /api/leads/
Internal Server Error: /api/leads/
Traceback (most recent call last):
  File "/home/ubuntu/venv/lib/python3.8/site-packages/kombu/utils/functional.py", line 30, in __call__
    return self.__value__
AttributeError: 'ChannelPromise' object has no attribute '__value__'

During handling of the above exception, another exception occurred:

Traceback (most recent call last):
  File "/home/ubuntu/venv/lib/python3.8/site-packages/kombu/connection.py", line 446, in _reraise_as_library_errors
    yield
  File "/home/ubuntu/venv/lib/python3.8/site-packages/kombu/connection.py", line 433, in _ensure_connection
    return retry_over_time(
  File "/home/ubuntu/venv/lib/python3.8/site-packages/kombu/utils/functional.py", line 312, in retry_over_time
    return fun(*args, **kwargs)
  File "/home/ubuntu/venv/lib/python3.8/site-packages/kombu/connection.py", line 877, in _connection_factory
    self._connection = self._establish_connection()
  File "/home/ubuntu/venv/lib/python3.8/site-packages/kombu/connection.py", line 812, in _establish_connection
    conn = self.transport.establish_connection()
  File "/home/ubuntu/venv/lib/python3.8/site-packages/kombu/transport/pyamqp.py", line 201, in establish_connection
    conn.connect()
  File "/home/ubuntu/venv/lib/python3.8/site-packages/amqp/connection.py", line 323, in connect
    self.transport.connect()
  File "/home/ubuntu/venv/lib/python3.8/site-packages/amqp/transport.py", line 129, in connect
    self._connect(self.host, self.port, self.connect_timeout)
  File "/home/ubuntu/venv/lib/python3.8/site-packages/amqp/transport.py", line 184, in _connect
    self.sock.connect(sa)
ConnectionRefusedError: [Errno 111] Connection refused

The above exception was the direct cause of the following exception:

Traceback (most recent call last):
  File "/home/ubuntu/venv/lib/python3.8/site-packages/django/core/handlers/exception.py", line 55, in inner
    response = get_response(request)
  File "/home/ubuntu/venv/lib/python3.8/site-packages/django/core/handlers/base.py", line 197, in _get_response
    response = wrapped_callback(request, *callback_args, **callback_kwargs)
  File "/home/ubuntu/venv/lib/python3.8/site-packages/django/views/decorators/csrf.py", line 54, in wrapped_view
    return view_func(*args, **kwargs)
  File "/home/ubuntu/venv/lib/python3.8/site-packages/django/views/generic/base.py", line 103, in view
    return self.dispatch(request, *args, **kwargs)
  File "/home/ubuntu/venv/lib/python3.8/site-packages/rest_framework/views.py", line 509, in dispatch
    response = self.handle_exception(exc)
  File "/home/ubuntu/venv/lib/python3.8/site-packages/rest_framework/views.py", line 469, in handle_exception
    self.raise_uncaught_exception(exc)
  File "/home/ubuntu/venv/lib/python3.8/site-packages/rest_framework/views.py", line 480, in raise_uncaught_exception
    raise exc
  File "/home/ubuntu/venv/lib/python3.8/site-packages/rest_framework/views.py", line 506, in dispatch
    response = handler(request, *args, **kwargs)
  File "/home/ubuntu/workspace/leads/views.py", line 182, in post
    send_email_to_assigned_user.delay(
  File "/home/ubuntu/venv/lib/python3.8/site-packages/celery/app/task.py", line 425, in delay
    return self.apply_async(args, kwargs)
  File "/home/ubuntu/venv/lib/python3.8/site-packages/celery/app/task.py", line 575, in apply_async
    return app.send_task(
  File "/home/ubuntu/venv/lib/python3.8/site-packages/celery/app/base.py", line 788, in send_task
    amqp.send_task_message(P, name, message, **options)
  File "/home/ubuntu/venv/lib/python3.8/site-packages/celery/app/amqp.py", line 510, in send_task_message
    ret = producer.publish(
  File "/home/ubuntu/venv/lib/python3.8/site-packages/kombu/messaging.py", line 177, in publish
    return _publish(
  File "/home/ubuntu/venv/lib/python3.8/site-packages/kombu/connection.py", line 523, in _ensured
    return fun(*args, **kwargs)
  File "/home/ubuntu/venv/lib/python3.8/site-packages/kombu/messaging.py", line 186, in _publish
    channel = self.channel
  File "/home/ubuntu/venv/lib/python3.8/site-packages/kombu/messaging.py", line 209, in _get_channel
    channel = self._channel = channel()
  File "/home/ubuntu/venv/lib/python3.8/site-packages/kombu/utils/functional.py", line 32, in __call__
    value = self.__value__ = self.__contract__()
  File "/home/ubuntu/venv/lib/python3.8/site-packages/kombu/messaging.py", line 225, in <lambda>
    channel = ChannelPromise(lambda: connection.default_channel)
  File "/home/ubuntu/venv/lib/python3.8/site-packages/kombu/connection.py", line 895, in default_channel
    self._ensure_connection(**conn_opts)
  File "/home/ubuntu/venv/lib/python3.8/site-packages/kombu/connection.py", line 433, in _ensure_connection
    return retry_over_time(
  File "/usr/lib/python3.8/contextlib.py", line 131, in __exit__
    self.gen.throw(type, value, traceback)
  File "/home/ubuntu/venv/lib/python3.8/site-packages/kombu/connection.py", line 450, in _reraise_as_library_errors
    raise ConnectionError(str(exc)) from exc
kombu.exceptions.OperationalError: [Errno 111] Connection refused
Not Found: /api/auth/companies-list/
Not Found: /api/auth/companies-list/
Watching for file changes with StatReloader
Watching for file changes with StatReloader
Not Found: /
Not Found: /favicon.ico
Not Found: /api/
Internal Server Error: /api/leads/
Traceback (most recent call last):
  File "/home/ubuntu/venv/lib/python3.8/site-packages/django/db/models/fields/__init__.py", line 2018, in get_prep_value
    return int(value)
ValueError: invalid literal for int() with base 10: 'null'

The above exception was the direct cause of the following exception:

Traceback (most recent call last):
  File "/home/ubuntu/venv/lib/python3.8/site-packages/django/core/handlers/exception.py", line 55, in inner
    response = get_response(request)
  File "/home/ubuntu/workspace/common/middleware/get_company.py", line 35, in __call__
    self.process_request(request)
  File "/home/ubuntu/workspace/common/middleware/get_company.py", line 48, in process_request
    org = Org.objects.get(id=org_id)
  File "/home/ubuntu/venv/lib/python3.8/site-packages/django/db/models/manager.py", line 85, in manager_method
    return getattr(self.get_queryset(), name)(*args, **kwargs)
  File "/home/ubuntu/venv/lib/python3.8/site-packages/django/db/models/query.py", line 636, in get
    clone = self._chain() if self.query.combinator else self.filter(*args, **kwargs)
  File "/home/ubuntu/venv/lib/python3.8/site-packages/django/db/models/query.py", line 1420, in filter
    return self._filter_or_exclude(False, args, kwargs)
  File "/home/ubuntu/venv/lib/python3.8/site-packages/django/db/models/query.py", line 1438, in _filter_or_exclude
    clone._filter_or_exclude_inplace(negate, args, kwargs)
  File "/home/ubuntu/venv/lib/python3.8/site-packages/django/db/models/query.py", line 1445, in _filter_or_exclude_inplace
    self._query.add_q(Q(*args, **kwargs))
  File "/home/ubuntu/venv/lib/python3.8/site-packages/django/db/models/sql/query.py", line 1532, in add_q
    clause, _ = self._add_q(q_object, self.used_aliases)
  File "/home/ubuntu/venv/lib/python3.8/site-packages/django/db/models/sql/query.py", line 1562, in _add_q
    child_clause, needed_inner = self.build_filter(
  File "/home/ubuntu/venv/lib/python3.8/site-packages/django/db/models/sql/query.py", line 1478, in build_filter
    condition = self.build_lookup(lookups, col, value)
  File "/home/ubuntu/venv/lib/python3.8/site-packages/django/db/models/sql/query.py", line 1303, in build_lookup
    lookup = lookup_class(lhs, rhs)
  File "/home/ubuntu/venv/lib/python3.8/site-packages/django/db/models/lookups.py", line 27, in __init__
    self.rhs = self.get_prep_lookup()
  File "/home/ubuntu/venv/lib/python3.8/site-packages/django/db/models/lookups.py", line 341, in get_prep_lookup
    return super().get_prep_lookup()
  File "/home/ubuntu/venv/lib/python3.8/site-packages/django/db/models/lookups.py", line 85, in get_prep_lookup
    return self.lhs.output_field.get_prep_value(self.rhs)
  File "/home/ubuntu/venv/lib/python3.8/site-packages/django/db/models/fields/__init__.py", line 2020, in get_prep_value
    raise e.__class__(
ValueError: Field 'id' expected a number but got 'null'.
Internal Server Error: /api/leads/
Traceback (most recent call last):
  File "/home/ubuntu/venv/lib/python3.8/site-packages/django/db/models/fields/__init__.py", line 2018, in get_prep_value
    return int(value)
ValueError: invalid literal for int() with base 10: 'null'

The above exception was the direct cause of the following exception:

Traceback (most recent call last):
  File "/home/ubuntu/venv/lib/python3.8/site-packages/django/core/handlers/exception.py", line 55, in inner
    response = get_response(request)
  File "/home/ubuntu/workspace/common/middleware/get_company.py", line 35, in __call__
    self.process_request(request)
  File "/home/ubuntu/workspace/common/middleware/get_company.py", line 48, in process_request
    org = Org.objects.get(id=org_id)
  File "/home/ubuntu/venv/lib/python3.8/site-packages/django/db/models/manager.py", line 85, in manager_method
    return getattr(self.get_queryset(), name)(*args, **kwargs)
  File "/home/ubuntu/venv/lib/python3.8/site-packages/django/db/models/query.py", line 636, in get
    clone = self._chain() if self.query.combinator else self.filter(*args, **kwargs)
  File "/home/ubuntu/venv/lib/python3.8/site-packages/django/db/models/query.py", line 1420, in filter
    return self._filter_or_exclude(False, args, kwargs)
  File "/home/ubuntu/venv/lib/python3.8/site-packages/django/db/models/query.py", line 1438, in _filter_or_exclude
    clone._filter_or_exclude_inplace(negate, args, kwargs)
  File "/home/ubuntu/venv/lib/python3.8/site-packages/django/db/models/query.py", line 1445, in _filter_or_exclude_inplace
    self._query.add_q(Q(*args, **kwargs))
  File "/home/ubuntu/venv/lib/python3.8/site-packages/django/db/models/sql/query.py", line 1532, in add_q
    clause, _ = self._add_q(q_object, self.used_aliases)
  File "/home/ubuntu/venv/lib/python3.8/site-packages/django/db/models/sql/query.py", line 1562, in _add_q
    child_clause, needed_inner = self.build_filter(
  File "/home/ubuntu/venv/lib/python3.8/site-packages/django/db/models/sql/query.py", line 1478, in build_filter
    condition = self.build_lookup(lookups, col, value)
  File "/home/ubuntu/venv/lib/python3.8/site-packages/django/db/models/sql/query.py", line 1303, in build_lookup
    lookup = lookup_class(lhs, rhs)
  File "/home/ubuntu/venv/lib/python3.8/site-packages/django/db/models/lookups.py", line 27, in __init__
    self.rhs = self.get_prep_lookup()
  File "/home/ubuntu/venv/lib/python3.8/site-packages/django/db/models/lookups.py", line 341, in get_prep_lookup
    return super().get_prep_lookup()
  File "/home/ubuntu/venv/lib/python3.8/site-packages/django/db/models/lookups.py", line 85, in get_prep_lookup
    return self.lhs.output_field.get_prep_value(self.rhs)
  File "/home/ubuntu/venv/lib/python3.8/site-packages/django/db/models/fields/__init__.py", line 2020, in get_prep_value
    raise e.__class__(
ValueError: Field 'id' expected a number but got 'null'.
Bad Request: /api/auth/login/
Watching for file changes with StatReloader
